Workbook

Sheet SUMMARY
A1: SN | B1: ITEM DESCRIPTION | C1: UoM | D1: QTY
A2: 1 | B2: CABLE INFRASTRUCTURE | C2: m | D2: =SUM('TOTALS(PASSIVE)'!C20,'TOTALS(PASSIVE)'!J20) -> 7268857.6
A3: 2 | B3: POPs | C3: unit | D3: ='TOTALS(ACTIVE)'!C20 -> 54
A4: 3 | B4: CORE DEVICES | C4: unit | D4: =SUM('TOTALS(ACTIVE)'!G20:AC20) -> 102
A5: 4 | B5: CUSTOMER SITES | C5: unit | D5: =SUM('TOTALS(ACTIVE)'!D20:F20) -> 1446
B7: ECG
A8: SN | B8: ITEM DESCRIPTION | C8: UoM | D8: QTY
A9: 1 | B9: CABLE INFRASTRUCTURE | C9: m | D9: =SUM('TOTALS(PASSIVE)'!C3:C10,'TOTALS(PASSIVE)'!J3:J10) -> 5603040.6
A10: 2 | B10: POPs | C10: unit | D10: =SUM('TOTALS(ACTIVE)'!C3:C10) -> 47
A11: 3 | B11: CORE DEVICES | C11: unit | D11: =SUM('TOTALS(ACTIVE)'!G22:AC22) -> 95
A12: 4 | B12: CUSTOMER SITES | C12: unit | D12: =SUM('TOTALS(ACTIVE)'!D22:F22) -> 1442
B14: NEDCO
A15: SN | B15: ITEM DESCRIPTION | C15: UoM | D15: QTY
A16: 1 | B16: CABLE INFRASTRUCTURE | C16: m | D16: =SUM('TOTALS(PASSIVE)'!C11:C18,'TOTALS(PASSIVE)'!J11:J18) -> 1665817
A17: 2 | B17: POPs | C17: unit | D17: ='TOTALS(ACTIVE)'!C23 -> 7
A18: 3 | B18: CORE DEVICES | C18: unit | D18: =SUM('TOTALS(ACTIVE)'!G23:AC23) -> 7
A19: 4 | B19: CUSTOMER SITES | C19: unit | D19: =SUM('TOTALS(ACTIVE)'!D23:F23) -> 4

Sheet AGE
A1: SN | B1: AGE | C1: NUMBER OF POPs(qty) | D1: CPE
D2: MIKROTIK | E2: ONT | F2: Master Backhaul DISTANCE | G2: Master Metro DISTANCE | H2: Total
A3: 1 | B3: 2020 | C3: =COUNTIF('PoP & EQUIPMENT'!$F$6:$F$83,AGE!B3) -> 12 | D3: {=COUNTIFS('MASTER-METRO'!O:O,AGE!B3:B9,'MASTER-METRO'!M:M,AGE!D2)} -> 36 | E3: {=COUNTIFS('MASTER-METRO'!O:O,AGE!B3:B9,'MASTER-METRO'!M:M,AGE!E2)} -> 32 | F3: {=SUMIFS('MASTER-BACKHAUL'!H:H,'MASTER-BACKHAUL'!K:K,AGE!B3:B9)} -> 144000 | G3: {=SUMIFS('MASTER-METRO'!J:J,'MASTER-METRO'!O:O,AGE!B3:B9)} -> 174291.55 | H3: =F3+G3 -> 318291.55
A4: 2 | B4: 2021 | C4: =COUNTIF('PoP & EQUIPMENT'!$F$6:$F$83,AGE!B4) -> 9 | D4: 176 | E4: 203 | F4: 599729.8 | G4: 759003.65 | H4: =F4+G4 -> 1358733.4
A5: 3 | B5: 2022 | C5: =COUNTIF('PoP & EQUIPMENT'!$F$6:$F$83,AGE!B5) -> 11 | D5: 91 | E5: 94 | F5: 685000 | G5: 358077.85 | H5: =F5+G5 -> 1043077.8
A6: 4 | B6: 2023 | C6: =COUNTIF('PoP & EQUIPMENT'!$F$6:$F$83,AGE!B6) -> 12 | D6: 170 | E6: 193 | F6: 2303406 | G6: 376070.9 | H6: =F6+G6 -> 2679476.9
A7: 5 | B7: 2024 | C7: =COUNTIF('PoP & EQUIPMENT'!$F$6:$F$83,AGE!B7) -> 10 | D7: 80 | E7: 306 | F7: 185000 | G7: 323114 | H7: =F7+G7 -> 508114
A8: 6 | B8: 2025 | C8: =COUNTIF('PoP & EQUIPMENT'!$F$6:$F$83,AGE!B8) -> 0 | D8: 57 | E8: 2 | F8: 701601 | G8: 248037.1 | H8: =F8+G8 -> 949638.1
D9: 0 | E9: 0 | F9: 0 | G9: 0 | H9: =F9+G9 -> 0
B10: TOTAL | C10: =SUM(C3:C9) -> 54 | D10: =SUM(D3:D9) -> 610 | E10: =SUM(E3:E9) -> 830 | F10: =SUM(F3:F9) -> 4618736.8 | G10: =SUM(G3:G9) -> 2238595 | H10: =SUM(H3:H9) -> 6857331.8

Sheet TOTALS(ACTIVE)
A1: SN | B1: REGION | C1: NUMBER OF POPs(qty) | D1: CPE | G1: ROUTERS | K1: OLTS | O1: SWITCHES | Z1: SERVERS
D2: MIKROTIK | E2: VSOL 2DAC | F2: ONT | G2: Mikrotik CCR1072-1G-8S+ | H2: Mikrotik CCR2216-1G-12XS-2XQ | I2: Mikrotik RB5009UG+S+ | J2: Cisco ASR1001-X | K2: VSOL OLT | L2: Furukawa OLT LD3008 | M2: Furukawa FK-OLT-G2500_SFU | N2: Furukawa OLT LD3032 | O2: Mikrotik CRS326-24S+2Q+ | P2: Mikrotik CRS305-1G-4S+ | Q2: Mikrotik CRS328-4C-20S-4S+ | R2: Mikrotik CRS317-1G-16S+ | S2: Mikrotik CRS510-8XS-2XQ | T2: FS Campus Switch (S5860-20SQ) | U2: Cisco WS-C3850-24P | V2: PLANET MGSW-28240F 24G + 4 10G | W2: PLANET MGSW-24160F Managed Switch | X2: Raisecom Switch RAX721-A | Y2: Raisecom Switch RAX711-C-R | Z2: HP ProLiant DL380p Gen8 | AA2: Dell PowerEdge R730 | AB2: HP ProLiant DL360 G7 | AC2: 24Online Server
A3: 1 | B3: ASHANTI | C3: =COUNTIF('PoP & EQUIPMENT'!$B$6:$B$83,'TOTALS(ACTIVE)'!B3) -> 4 | D3: {=COUNTIFS('MASTER-METRO'!B:B,'TOTALS(ACTIVE)'!B3:B18,'MASTER-METRO'!M:M,'TOTALS(ACTIVE)'!D2)} -> 44 | E3: {=COUNTIFS('MASTER-METRO'!B:B,'TOTALS(ACTIVE)'!B3:B18,'MASTER-METRO'!L:L,'TOTALS(ACTIVE)'!E2)} -> 0 | F3: {=COUNTIFS('MASTER-METRO'!B:B,'TOTALS(ACTIVE)'!B3:B18,'MASTER-METRO'!M:M,'TOTALS(ACTIVE)'!F2)} -> 53 | G3: {=SUMIF('PoP & EQUIPMENT'!$B:$B,'TOTALS(ACTIVE)'!$B$3:$B$18,'PoP & EQUIPMENT'!Y:AU)} -> 0 | H3: {=SUMIF('PoP & EQUIPMENT'!$B:$B,'TOTALS(ACTIVE)'!$B$3:$B$18,'PoP & EQUIPMENT'!Z:AV)} -> 4 | I3: {=SUMIF('PoP & EQUIPMENT'!$B:$B,'TOTALS(ACTIVE)'!$B$3:$B$18,'PoP & EQUIPMENT'!AF:BA)} -> 0 | J3: {=SUMIF('PoP & EQUIPMENT'!$B:$B,'TOTALS(ACTIVE)'!$B$3:$B$18,'PoP & EQUIPMENT'!AL:BG)} -> 0 | K3: {=SUMIF('PoP & EQUIPMENT'!$B:$B,'TOTALS(ACTIVE)'!$B$3:$B$18,'PoP & EQUIPMENT'!AG:BB)} -> 0 | L3: {=SUMIF('PoP & EQUIPMENT'!$B:$B,'TOTALS(ACTIVE)'!$B$3:$B$18,'PoP & EQUIPMENT'!AH:BC)} -> 0 | M3: {=SUMIF('PoP & EQUIPMENT'!$B:$B,'TOTALS(ACTIVE)'!$B$3:$B$18,'PoP & EQUIPMENT'!AI:BD)} -> 0 | N3: {=SUMIF('PoP & EQUIPMENT'!$B:$B,'TOTALS(ACTIVE)'!$B$3:$B$18,'PoP & EQUIPMENT'!AJ:BE)} -> 1 | O3: {=SUMIF('PoP & EQUIPMENT'!$B:$B,'TOTALS(ACTIVE)'!$B$3:$B$18,'PoP & EQUIPMENT'!AA:AW)} -> 0 | P3: {=SUMIF('PoP & EQUIPMENT'!$B:$B,'TOTALS(ACTIVE)'!$B$3:$B$18,'PoP & EQUIPMENT'!X:AT)} -> 0 | Q3: {=SUMIF('PoP & EQUIPMENT'!$B:$B,'TOTALS(ACTIVE)'!$B$3:$B$18,'PoP & EQUIPMENT'!AB:AX)} -> 1 | R3: {=SUMIF('PoP & EQUIPMENT'!$B:$B,'TOTALS(ACTIVE)'!$B$3:$B$18,'PoP & EQUIPMENT'!AC:AY)} -> 0 | S3: {=SUMIF('PoP & EQUIPMENT'!$B:$B,'TOTALS(ACTIVE)'!$B$3:$B$18,'PoP & EQUIPMENT'!AD:AZ)} -> 0 | T3: {=SUMIF('PoP & EQUIPMENT'!$B:$B,'TOTALS(ACTIVE)'!$B$3:$B$18,'PoP & EQUIPMENT'!AK:BF)} -> 0 | U3: {=SUMIF('PoP & EQUIPMENT'!$B:$B,'TOTALS(ACTIVE)'!$B$3:$B$18,'PoP & EQUIPMENT'!AM:BH)} -> 0 | V3: {=SUMIF('PoP & EQUIPMENT'!$B:$B,'TOTALS(ACTIVE)'!$B$3:$B$18,'PoP & EQUIPMENT'!AN:BI)} -> 0 | W3: {=SUMIF('PoP & EQUIPMENT'!$B:$B,'TOTALS(ACTIVE)'!$B$3:$B$18,'PoP & EQUIPMENT'!AO:BJ)} -> 1 | X3: {=SUMIF('PoP & EQUIPMENT'!$B:$B,'TOTALS(ACTIVE)'!$B$3:$B$18,'PoP & EQUIPMENT'!AP:BK)} -> 2 | Y3: {=SUMIF('PoP & EQUIPMENT'!$B:$B,'TOTALS(ACTIVE)'!$B$3:$B$18,'PoP & EQUIPMENT'!AQ:BL)} -> 0 | Z3: {=SUMIF('PoP & EQUIPMENT'!$B:$B,'TOTALS(ACTIVE)'!$B$3:$B$18,'PoP & EQUIPMENT'!AR:BM)} -> 0 | AA3: {=SUMIF('PoP & EQUIPMENT'!$B:$B,'TOTALS(ACTIVE)'!$B$3:$B$18,'PoP & EQUIPMENT'!AS:BN)} -> 0 | AB3: {=SUMIF('PoP & EQUIPMENT'!$B:$B,'TOTALS(ACTIVE)'!$B$3:$B$18,'PoP & EQUIPMENT'!AT:BO)} -> 0 | AC3: {=SUMIF('PoP & EQUIPMENT'!$B:$B,'TOTALS(ACTIVE)'!$B$3:$B$18,'PoP & EQUIPMENT'!AU:BP)} -> 0
A4: 2 | B4: CENTRAL | C4: =COUNTIF('PoP & EQUIPMENT'!$B$6:$B$83,'TOTALS(ACTIVE)'!B4) -> 5 | D4: 38 | E4: 0 | F4: 2 | G4: 1 | H4: 2 | I4: 0 | J4: 0 | K4: 0 | L4: 0 | M4: 0 | N4: 0 | O4: 0 | P4: 0 | Q4: 0 | R4: 0 | S4: 2 | T4: 0 | U4: 0 | V4: 0 | W4: 0 | X4: 2 | Y4: 0 | Z4: 0 | AA4: 0 | AB4: 0 | AC4: 0
A5: 3 | B5: EASTERN | C5: =COUNTIF('PoP & EQUIPMENT'!$B$6:$B$83,'TOTALS(ACTIVE)'!B5) -> 9 | D5: 55 | E5: 0 | F5: 7 | G5: 2 | H5: 5 | I5: 0 | J5: 0 | K5: 1 | L5: 0 | M5: 0 | N5: 0 | O5: 0 | P5: 0 | Q5: 1 | R5: 0 | S5: 2 | T5: 1 | U5: 0 | V5: 1 | W5: 0 | X5: 1 | Y5: 0 | Z5: 0 | AA5: 0 | AB5: 0 | AC5: 0
A6: 4 | B6: GREATER ACCRA | C6: =COUNTIF('PoP & EQUIPMENT'!$B$6:$B$83,'TOTALS(ACTIVE)'!B6) -> 15 | D6: 384 | E6: 0 | F6: 759 | G6: 1 | H6: 12 | I6: 2 | J6: 1 | K6: 1 | L6: 1 | M6: 1 | N6: 6 | O6: 0 | P6: 0 | Q6: 2 | R6: 1 | S6: 0 | T6: 3 | U6: 2 | V6: 3 | W6: 1 | X6: 4 | Y6: 1 | Z6: 1 | AA6: 1 | AB6: 2 | AC6: 1
A7: 5 | B7: VOLTA | C7: =COUNTIF('PoP & EQUIPMENT'!$B$6:$B$83,'TOTALS(ACTIVE)'!B7) -> 8 | D7: 32 | E7: 0 | F7: 0 | G7: 0 | H7: 2 | I7: 0 | J7: 0 | K7: 0 | L7: 0 | M7: 0 | N7: 0 | O7: 0 | P7: 2 | Q7: 0 | R7: 2 | S7: 1 | T7: 0 | U7: 0 | V7: 0 | W7: 0 | X7: 0 | Y7: 0 | Z7: 0 | AA7: 0 | AB7: 0 | AC7: 0
A8: 6 | B8: OTI | C8: =COUNTIF('PoP & EQUIPMENT'!$B$6:$B$83,'TOTALS(ACTIVE)'!B8) -> 0 | D8: 0 | E8: 0 | F8: 0 | G8: 0 | H8: 0 | I8: 0 | J8: 0 | K8: 0 | L8: 0 | M8: 0 | N8: 0 | O8: 0 | P8: 0 | Q8: 0 | R8: 0 | S8: 0 | T8: 0 | U8: 0 | V8: 0 | W8: 0 | X8: 0 | Y8: 0 | Z8: 0 | AA8: 0 | AB8: 0 | AC8: 0
A9: 7 | B9: WESTERN | C9: =COUNTIF('PoP & EQUIPMENT'!$B$6:$B$83,'TOTALS(ACTIVE)'!B9) -> 6 | D9: 58 | E9: 0 | F9: 10 | G9: 0 | H9: 2 | I9: 1 | J9: 0 | K9: 1 | L9: 0 | M9: 0 | N9: 0 | O9: 0 | P9: 0 | Q9: 0 | R9: 1 | S9: 3 | T9: 0 | U9: 0 | V9: 1 | W9: 0 | X9: 1 | Y9: 1 | Z9: 0 | AA9: 0 | AB9: 0 | AC9: 0
A10: 8 | B10: WESTERN NORTH | C10: =COUNTIF('PoP & EQUIPMENT'!$B$6:$B$83,'TOTALS(ACTIVE)'!B10) -> 0 | D10: 0 | E10: 0 | F10: 0 | G10: 0 | H10: 0 | I10: 0 | J10: 0 | K10: 0 | L10: 0 | M10: 0 | N10: 0 | O10: 0 | P10: 0 | Q10: 0 | R10: 0 | S10: 0 | T10: 0 | U10: 0 | V10: 0 | W10: 0 | X10: 0 | Y10: 0 | Z10: 0 | AA10: 0 | AB10: 0 | AC10: 0
A11: 9 | B11: BONO EAST | C11: =COUNTIF('PoP & EQUIPMENT'!$B$6:$B$83,'TOTALS(ACTIVE)'!B11) -> 0 | D11: 0 | E11: 0 | F11: 0 | G11: 0 | H11: 0 | I11: 0 | J11: 0 | K11: 0 | L11: 0 | M11: 0 | N11: 0 | O11: 0 | P11: 0 | Q11: 0 | R11: 0 | S11: 0 | T11: 0 | U11: 0 | V11: 0 | W11: 0 | X11: 0 | Y11: 0 | Z11: 0 | AA11: 0 | AB11: 0 | AC11: 0
A12: 10 | B12: AHAFO | C12: =COUNTIF('PoP & EQUIPMENT'!$B$6:$B$83,'TOTALS(ACTIVE)'!B12) -> 1 | D12: 0 | E12: 0 | F12: 0 | G12: 0 | H12: 0 | I12: 0 | J12: 0 | K12: 0 | L12: 0 | M12: 0 | N12: 0 | O12: 0 | P12: 1 | Q12: 0 | R12: 0 | S12: 0 | T12: 0 | U12: 0 | V12: 0 | W12: 0 | X12: 0 | Y12: 0 | Z12: 0 | AA12: 0 | AB12: 0 | AC12: 0
A13: 11 | B13: BRONG AHAFO | C13: =COUNTIF('PoP & EQUIPMENT'!$B$6:$B$83,'TOTALS(ACTIVE)'!B13) -> 1 | D13: 2 | E13: 0 | F13: 0 | G13: 1 | H13: 0 | I13: 0 | J13: 0 | K13: 0 | L13: 0 | M13: 0 | N13: 0 | O13: 0 | P13: 0 | Q13: 0 | R13: 0 | S13: 0 | T13: 0 | U13: 0 | V13: 0 | W13: 0 | X13: 0 | Y13: 0 | Z13: 0 | AA13: 0 | AB13: 0 | AC13: 0
A14: 12 | B14: SAVANNAH | C14: =COUNTIF('PoP & EQUIPMENT'!$B$6:$B$83,'TOTALS(ACTIVE)'!B14) -> 1 | D14: 0 | E14: 0 | F14: 0 | G14: 0 | H14: 0 | I14: 0 | J14: 0 | K14: 0 | L14: 0 | M14: 0 | N14: 0 | O14: 0 | P14: 0 | Q14: 0 | R14: 0 | S14: 0 | T14: 0 | U14: 0 | V14: 0 | W14: 0 | X14: 0 | Y14: 0 | Z14: 0 | AA14: 0 | AB14: 0 | AC14: 0
A15: 13 | B15: NORTHERN | C15: =COUNTIF('PoP & EQUIPMENT'!$B$6:$B$83,'TOTALS(ACTIVE)'!B15) -> 2 | D15: 2 | E15: 0 | F15: 0 | G15: 0 | H15: 1 | I15: 0 | J15: 0 | K15: 0 | L15: 0 | M15: 0 | N15: 0 | O15: 0 | P15: 1 | Q15: 1 | R15: 0 | S15: 0 | T15: 0 | U15: 0 | V15: 0 | W15: 0 | X15: 0 | Y15: 0 | Z15: 0 | AA15: 0 | AB15: 0 | AC15: 0
... A18: 16 | B18: UPPER WEST | C18: =COUNTIF('PoP & EQUIPMENT'!$B$6:$B$83,'TOTALS(ACTIVE)'!B18) -> 0 | D18: 0 | E18: 0 | F18: 0 | G18: 0 | H18: 0 | I18: 0 | J18: 0 | K18: 0 | L18: 0 | M18: 0 | N18: 0 | O18: 0 | P18: 0 | Q18: 0 | R18: 0 | S18: 0 | T18: 0 | U18: 0 | V18: 0 | W18: 0 | X18: 0 | Y18: 0 | Z18: 0 | AA18: 0 | AB18: 0 | AC18: 0
B20: TOTAL | C20: =SUM(C3:C19) -> 54 | D20: =SUM(D3:D19) -> 615 | F20: =SUM(F3:F19) -> 831 | G20: =SUM(G3:G19) -> 6 | H20: =SUM(H3:H19) -> 28 | I20: =SUM(I3:I19) -> 3 | J20: =SUM(J3:J19) -> 1 | K20: =SUM(K3:K19) -> 3 | L20: =SUM(L3:L19) -> 1 | M20: =SUM(M3:M19) -> 1 | ... AC20: =SUM(AC3:AC19) -> 1
B22: TOTAL(ECG) | C22: =SUM(C3:C10) -> 47 | D22: =SUM(D3:D10) -> 611 | F22: =SUM(F3:F10) -> 831 | G22: =SUM(G3:G10) -> 4 | H22: =SUM(H3:H10) -> 27 | I22: =SUM(I3:I10) -> 3 | J22: =SUM(J3:J10) -> 1 | K22: =SUM(K3:K10) -> 3 | L22: =SUM(L3:L10) -> 1 | M22: =SUM(M3:M10) -> 1 | ... AC22: =SUM(AC3:AC10) -> 1
B23: TOTAL(NEDCO) | C23: =SUM(C11:C18) -> 7 | D23: =SUM(D11:D18) -> 4 | F23: =SUM(F11:F18) -> 0 | G23: =SUM(G11:G18) -> 2 | H23: =SUM(H11:H18) -> 1 | I23: =SUM(I11:I18) -> 0 | J23: =SUM(J11:J18) -> 0 | K23: =SUM(K11:K18) -> 0 | L23: =SUM(L11:L18) -> 0 | M23: =SUM(M11:M18) -> 0 | ... AC23: =SUM(AC11:AC18) -> 0

Sheet TOTALS(PASSIVE)
A1: SN | B1: REGION | C1: METRO NETWORK | J1: BACKHAUL NETWORK
C2: Distance(m) | D2: Pole Brackets (pcs) | E2: Tension Clamps (pcs) | F2: Suspensions (pcs) | G2: Buckles (pcs) | H2: Steel Band (m) | I2: Closures (pcs) | J2: Distance(m) | K2: Pole Brackets (pcs) | L2: Tension Clamps (pcs) | M2: Suspensions (pcs) | N2: Buckles (pcs) | O2: Steel Band (m) | P2: Closures (pcs)
A3: 1 | B3: ASHANTI | C3: {=SUMIF('MASTER-METRO'!B:B,'TOTALS(PASSIVE)'!B3:B18,'MASTER-METRO'!J:J)} -> 210301.3 | D3: {=SUMIF('MASTER-METRO'!B:B,'TOTALS(PASSIVE)'!B3:B18,'MASTER-ACCESSORIES- METRO'!G:G)} -> 1155.088 | E3: {=SUMIF('MASTER-ACCESSORIES- METRO'!B:B,'TOTALS(PASSIVE)'!B3:B18,'MASTER-ACCESSORIES- METRO'!H:H)} -> 2521.3977 | F3: {=SUMIF('MASTER-ACCESSORIES- METRO'!B:B,'TOTALS(PASSIVE)'!B3:B18,'MASTER-ACCESSORIES- METRO'!I:I)} -> 1891.0483 | G3: {=SUMIF('MASTER-ACCESSORIES- METRO'!B:B,'TOTALS(PASSIVE)'!B3:B18,'MASTER-ACCESSORIES- METRO'!J:J)} -> 3151.7471 | H3: {=SUMIF('MASTER-ACCESSORIES- METRO'!B:B,'TOTALS(PASSIVE)'!B3:B18,'MASTER-ACCESSORIES- METRO'!K:K)} -> 3151.7471 | I3: {=SUMIF('MASTER-ACCESSORIES- METRO'!B:B,'TOTALS(PASSIVE)'!B3:B18,'MASTER-ACCESSORIES- METRO'!L:L)} -> 220.21558 | J3: {=SUMIF('MASTER-BACKHAUL'!B:B,'TOTALS(PASSIVE)'!B3:B18,'MASTER-BACKHAUL'!H:H)} -> 445800 | K3: {=SUMIF('MASTER-ACCESSORIES - BACKHAUL'!B:B,'TOTALS(PASSIVE)'!B3:B18,'MASTER-ACCESSORIES - BACKHAUL'!F:F)} -> 3020.8 | L3: {=SUMIF('MASTER-ACCESSORIES - BACKHAUL'!B:B,'TOTALS(PASSIVE)'!B3:B18,'MASTER-ACCESSORIES - BACKHAUL'!G:G)} -> 6041.6 | M3: {=SUMIF('MASTER-ACCESSORIES - BACKHAUL'!B:B,'TOTALS(PASSIVE)'!B3:B18,'MASTER-ACCESSORIES - BACKHAUL'!H:H)} -> 4531.2 | N3: {=SUMIF('MASTER-ACCESSORIES - BACKHAUL'!B:B,'TOTALS(PASSIVE)'!B3:B18,'MASTER-ACCESSORIES - BACKHAUL'!I:I)} -> 7552 | O3: {=SUMIF('MASTER-ACCESSORIES - BACKHAUL'!B:B,'TOTALS(PASSIVE)'!B3:B18,'MASTER-ACCESSORIES - BACKHAUL'!J:J)} -> 7552 | P3: {=SUMIF('MASTER-ACCESSORIES - BACKHAUL'!B:B,'TOTALS(PASSIVE)'!B3:B18,'MASTER-ACCESSORIES - BACKHAUL'!K:K)} -> 143.95
A4: 2 | B4: CENTRAL | C4: 119608 | D4: 631.55086 | E4: 1414.1371 | F4: 1060.6029 | G4: 1767.6714 | H4: 1767.6714 | I4: 102.65675 | J4: 520000 | K4: 2968.9143 | L4: 5937.8286 | M4: 4453.3714 | N4: 7422.2857 | O4: 7422.2857 | P4: 137.75
A5: 3 | B5: EASTERN | C5: 208681.7 | D5: 1218.518 | E5: 2428.3623 | F5: 1821.2717 | G5: 3035.4529 | H5: 3035.4529 | I5: 131.72043 | J5: 521400 | K5: 2983.0286 | L5: 5966.0571 | M5: 4474.5429 | N5: 7457.5714 | O5: 7457.5714 | P5: 139.35
A6: 4 | B6: GREATER ACCRA | C6: 1507321.2 | D6: 9769.854 | E6: 18453.111 | F6: 13839.834 | G6: 23066.389 | H6: 23066.389 | I6: 2203.6018 | J6: 444800 | K6: 3277.0286 | L6: 6554.0571 | M6: 4915.5429 | N6: 8192.5714 | O6: 8192.5714 | P6: 166.95
A7: 5 | B7: VOLTA | C7: 25159 | D7: 151.97714 | E7: 327.53143 | F7: 245.64857 | G7: 409.41429 | H7: 409.41429 | I7: 56.28975 | J7: 691135.8 | K7: 3954.5474 | L7: 7909.0949 | M7: 5931.8211 | N7: 9886.3686 | O7: 9886.3686 | P7: 185.78395
A8: 6 | B8: OTI | C8: 0 | D8: 0 | E8: 0 | F8: 0 | G8: 0 | H8: 0 | I8: 0 | J8: 0 | K8: 0 | L8: 0 | M8: 0 | N8: 0 | O8: 0 | P8: 0
A9: 7 | B9: WESTERN | C9: 191833.55 | D9: 1072.1423 | E9: 2237.732 | F9: 1678.299 | G9: 2797.165 | H9: 2797.165 | I9: 142.28789 | J9: 483000 | K9: 2293.8286 | L9: 4587.6571 | M9: 3440.7429 | N9: 5734.5714 | O9: 5734.5714 | P9: 106.25
A10: 8 | B10: WESTERN NORTH | C10: 0 | D10: 0 | E10: 0 | F10: 0 | G10: 0 | H10: 0 | I10: 0 | J10: 234000 | K10: 1338.3429 | L10: 2676.6857 | M10: 2007.5143 | N10: 3345.8571 | O10: 3345.8571 | P10: 61.5
A11: 9 | B11: BONO EAST | C11: 0 | D11: 0 | E11: 0 | F11: 0 | G11: 0 | H11: 0 | I11: 0 | J11: 82000 | K11: 469.37143 | L11: 938.74286 | M11: 704.05714 | N11: 1173.4286 | O11: 1173.4286 | P11: 22.5
A12: 10 | B12: AHAFO | C12: 0 | D12: 0 | E12: 0 | F12: 0 | G12: 0 | H12: 0 | I12: 0 | J12: 40000 | K12: 228.97143 | L12: 457.94286 | M12: 343.45714 | N12: 572.42857 | O12: 572.42857 | P12: 11
A13: 11 | B13: BRONG AHAFO | C13: 1948 | D13: 29.702857 | E13: 99.862857 | F13: 74.897143 | G13: 124.82857 | H13: 124.82857 | I13: 21.8345 | J13: 395601 | K13: 1078.92 | L13: 2157.84 | M13: 1618.38 | N13: 2697.3 | O13: 2697.3 | P13: 50.15025
A14: 12 | B14: SAVANNAH | C14: 0 | D14: 0 | E14: 0 | F14: 0 | G14: 0 | H14: 0 | I14: 0 | J14: 217000 | K14: 909.77143 | L14: 1819.5429 | M14: 1364.6571 | N14: 2274.4286 | O14: 2274.4286 | P14: 42.75
A15: 13 | B15: NORTHERN | C15: 2268 | D15: 2.5142857 | E15: 663.30286 | F15: 497.47714 | G15: 829.12857 | H15: 829.12857 | I15: 43.98475 | J15: 350000 | K15: 1910.5714 | L15: 3821.1429 | M15: 2865.8571 | N15: 4776.4286 | O15: 4776.4286 | P15: 88.5
... A18: 16 | B18: UPPER WEST | C18: 0 | D18: 0 | E18: 0 | F18: 0 | G18: 0 | H18: 0 | I18: 0 | J18: 279000 | K18: 1595.8857 | L18: 3191.7714 | M18: 2393.8286 | N18: 3989.7143 | O18: 3989.7143 | P18: 73.75
B20: TOTAL | C20: =SUM(C3:C19) -> 2267120.8 | D20: =SUM(D3:D19) -> 14031.347 | E20: =SUM(E3:E19) -> 28177.095 | F20: =SUM(F3:F19) -> 21132.821 | G20: =SUM(G3:G19) -> 35221.369 | H20: =SUM(H3:H19) -> 35221.369 | I20: =SUM(I3:I19) -> 2924.2665 | J20: =SUM(J3:J19) -> 5001736.8 | ... P20: =SUM(P3:P19) -> 1312.6842
B23: ECG | C23: =SUM(C3:C10) -> 2262904.8 | D23: =SUM(D3:D10) -> 13999.13 | E23: =SUM(E3:E10) -> 27382.272 | F23: =SUM(F3:F10) -> 20536.704 | G23: =SUM(G3:G10) -> 34227.84 | H23: =SUM(H3:H10) -> 34227.84 | I23: =SUM(I3:I10) -> 2856.7722 | J23: =SUM(J3:J10) -> 3340135.8 | ... P23: =SUM(P3:P10) -> 941.53395 | Q23: =SUM(C23:P23) -> 5925659.4
B24: NEDCO | C24: =SUM(C11:C18) -> 4216 | D24: =SUM(D11:D18) -> 32.217143 | E24: =SUM(E11:E18) -> 794.82286 | F24: =SUM(F11:F18) -> 596.11714 | G24: =SUM(G11:G18) -> 993.52857 | H24: =SUM(H11:H18) -> 993.52857 | I24: =SUM(I11:I18) -> 67.49425 | J24: =SUM(J11:J18) -> 1661601 | ... P24: =SUM(P11:P18) -> 371.15025 | Q24: =SUM(C24:P24) -> 1745564.9

Sheet PoP & EQUIPMENT
A3: SN | B3: REGION | C3: TERRITORY | D3: LOCATION | E3: COORDINATES | F3: AGE | G3: POP TYPE | H3: cabinet | T3: ODF | BT3: Power
H4: 4u | I4: 6u | J4: 9u | K4: 10u | L4: 12u | M4: 21u | N4: 22u | O4: 27u | P4: 29u | Q4: 32u | R4: 42u | S4: 9core | T4: 12core | U4: 24core | V4: 48core | W4: 96core | X4: Mikrotik CRS305-1G-4S+ | Y4: Mikrotik CCR1072-1G-8S+ | Z4: Mikrotik CCR2216-1G-12XS-2XQ | AA4: Mikrotik CRS326-24S+2Q+ | AB4: Mikrotik CRS328-4C-20S-4S+ | AC4: Mikrotik CRS317-1G-16S+ | AD4: Mikrotik CRS510-8XS-2XQ | AE4: Mikrotik CRS504-8XS-2XQ | AF4: Mikrotik RB5009UG+S+ | AG4: VSOL OLT | AH4: Furukawa OLT LD3008 | AI4: Furukawa FK-OLT-G2500_SFU | AJ4: Furukawa OLT LD3032 | AK4: FS Campus Switch (S5860-20SQ) | AL4: Cisco ASR1001-X | AM4: Cisco WS-C3850-24P | AN4: PLANET MGSW-28240F 24G + 4 10G | AO4: PLANET MGSW-24160F Managed Switch | AP4: Raisecom Switch RAX721-A | AQ4: Raisecom Switch RAX711-C-R | AR4: HP ProLiant DL380p Gen8 | AS4: Dell PowerEdge R730 | AT4: HP ProLiant DL360 G7 | AU4: 24Online Server | BE4: 10G(Simplex) | BN4: 10G(Duplex) | BS4: GPON | BT4: UPS | BU4: Stabilizer | BV4: battery bank | BY4: Inverter | CA4: AVR | CB4: Solar
AV5: Total | AW5: Copper | AX5: 2km | AY5: 3km | AZ5: 10km | BA5: 20km | BB5: 40km | BC5: 60km | BD5: 80km | BE5: Copper | BF5: 2km | BG5: 10km | BH5: 20km | BI5: 40km | BJ5: 60km | BK5: 80km | BL5: 100km | BM5: 120km | BN5: 2km | BO5: 10km | BP5: 80km | BQ5: 100km | BR5: 120km | BS5: 20km | BV5: battery Containment | BW5: 100AH | BX5: 200AH | BY5: 5KVA | BZ5: 3KVA
A6: 1 | B6: ASHANTI | C6: ECG | D6: OBUASI | E6: 6.204062 -1.677247 | F6: 2022 | G6: Indoor | H6: 1 | V6: 2 | Z6: 1 | AP6: 1 | AV6: =SUM(AW6:BS6) -> 8 | BA6: 2 | BC6: 1 | BD6: 1 | BL6: 3 | BN6: 1 | BX6: 2 | BZ6: 1
A7: 2 | B7: ASHANTI | C7: ECG | D7: KUMASI-ASANTEMAN | E7: 6.708774 -1.627550 | F7: 2020 | G7: Outdoor | N7: 1 | V7: 3 | Z7: 1 | AJ7: 1 | AO7: 1 | AV7: =SUM(AW7:BS7) -> 3 | AZ7: 1 | BD7: 1 | BG7: 1 | BV7: 1 | BX7: 4 | BY7: 1
A8: 3 | B8: ASHANTI | C8: ECG | D8: KUBEASE | E8: 6.675194 -1.380315 | F8: 2022 | G8: Indoor | H8: 1 | V8: 2 | Z8: 1 | AP8: 1 | AV8: =SUM(AW8:BS8) -> 7 | BA8: 2 | BD8: 1 | BG8: 1 | BI8: 1 | BK8: 1 | BL8: 1 | BX8: 2 | BZ8: 1
A9: 4 | B9: ASHANTI | C9: ECG | D9: KUMASI-ROMANHILL | E9: 6.696086 , -1.617477 | F9: 2020 | G9: Outdoor | N9: 1 | V9: 2 | Z9: 1 | AB9: 1 | AV9: =SUM(AW9:BS9) -> 29 | AZ9: 11 | BC9: 7 | BD9: 2 | BE9: 2 | BG9: 2 | BI9: 1 | BJ9: 1 | BK9: 2 | BL9: 1 | BV9: 1 | BX9: 4 | BY9: 1
B11: TOTAL | H11: =SUM(H6:H9) -> 2 | I11: =SUM(I6:I9) -> 0 | J11: =SUM(J6:J9) -> 0 | K11: =SUM(K6:K9) -> 0 | L11: =SUM(L6:L9) -> 0 | M11: =SUM(M6:M9) -> 0 | N11: =SUM(N6:N9) -> 2 | O11: =SUM(O6:O9) -> 0 | ... AC11: =SUM(AC6:AC9) -> 0 | AF11: =SUM(AF6:AF9) -> 0 | AH11: =SUM(AH6:AH9) -> 0 | AI11: =SUM(AI6:AI9) -> 0 | AJ11: =SUM(AJ6:AJ9) -> 1 | AK11: =SUM(AK6:AK9) -> 0 | AL11: =SUM(AL6:AL9) -> 0 | AM11: =SUM(AM6:AM9) -> 0 | AN11: =SUM(AN6:AN9) -> 0 | AO11: =SUM(AO6:AO9) -> 1 | ... AU11: =SUM(AU6:AU9) -> 0 | BT11: =SUM(BT6:BT9) -> 0 | BU11: =SUM(BU6:BU9) -> 0 | BW11: =SUM(BW6:BW9) -> 0 | BX11: =SUM(BX6:BX9) -> 12 | BY11: =SUM(BY6:BY9) -> 2 | BZ11: =SUM(BZ6:BZ9) -> 2 | CA11: =SUM(CA6:CA9) -> 0 | CB11: =SUM(CB6:CB9) -> 0
A13: 1 | B13: AHAFO | C13: NEDCO | D13: BECHEM | E13: 7.081587 -2.02320 | F13: 2023 | G13: Indoor | X13: 1 | AV13: =SUM(AW13:BS13) -> 3 | BD13: 1 | BQ13: 2
A14: 2 | B14: BRONG AHAFO | C14: NEDCO | D14: SUNYANI | E14: 7.319474, -2.317673 | F14: 2023 | G14: Indoor | Y14: 1 | AV14: =SUM(AW14:BS14) -> 8 | AZ14: 3 | BA14: 2 | BC14: 1 | BD14: 1 | BP14: 1
B16: TOTAL | H16: =SUM(H13:H14) -> 0 | I16: =SUM(I13:I14) -> 0 | J16: =SUM(J13:J14) -> 0 | K16: =SUM(K13:K14) -> 0 | L16: =SUM(L13:L14) -> 0 | M16: =SUM(M13:M14) -> 0 | N16: =SUM(N13:N14) -> 0 | O16: =SUM(O13:O14) -> 0 | ... AC16: =SUM(AC13:AC14) -> 0 | AF16: =SUM(AF13:AF14) -> 0 | AH16: =SUM(AH13:AH14) -> 0 | AI16: =SUM(AI13:AI14) -> 0 | AJ16: =SUM(AJ13:AJ14) -> 0 | AK16: =SUM(AK13:AK14) -> 0 | AL16: =SUM(AL13:AL14) -> 0 | AM16: =SUM(AM13:AM14) -> 0 | AN16: =SUM(AN13:AN14) -> 0 | AO16: =SUM(AO13:AO14) -> 0 | ... CB16: =SUM(CB13:CB14) -> 0
A18: 1 | B18: CENTRAL | C18: ECG | D18: CAPE COAST ECG OFFICE | E18: 5.117613 -1.244324 | F18: 2020 | G18: Indoor | V18: 3 | Z18: 1 | AP18: 1 | AV18: =SUM(AW18:BS18) -> 26 | AW18: 1 | AZ18: 1 | BA18: 16 | BC18: 3 | BD18: 1 | BE18: 2 | BK18: 1 | BL18: 1 | BX18: 4 | BY18: 1
A19: 2 | B19: CENTRAL | C19: ECG | D19: WINNEBA | E19: 5.379158 -0.652166 | F19: 2022 | G19: Outdoor | N19: 1 | Z19: 1 | AP19: 1 | AV19: =SUM(AW19:BS19) -> 9 | AW19: 1 | BA19: 4 | BD19: 1 | BE19: 2 | BK19: 1 | BW19: 4 | BY19: 1
A20: 4 | B20: CENTRAL | C20: ECG | D20: SWEDRU | E20: 5.535335 -0.692072 | F20: 2024 | G20: Outdoor | N20: 1 | Y20: 1 | AV20: =SUM(AW20:BS20) -> 2 | BJ20: 2
A21: 5 | B21: CENTRAL | C21: ECG | D21: MANKESSIM | E21: 5.2725239 -0.993339 | F21: 2023 | G21: Outdoor | AD21: 1 | AV21: =SUM(AW21:BS21) -> 3 | BA21: 1 | BJ21: 1 | BK21: 1
A22: 6 | B22: CENTRAL | C22: ECG | D22: ASSIN FOSU | E22: 5.690891 -1.2767645 | F22: 2024 | G22: Indoor | AD22: 1 | AV22: =SUM(AW22:BS22) -> 0
B24: TOTAL | H24: =SUM(H18:H21) -> 0 | I24: =SUM(I18:I21) -> 0 | J24: =SUM(J18:J21) -> 0 | K24: =SUM(K18:K21) -> 0 | L24: =SUM(L18:L21) -> 0 | M24: =SUM(M18:M21) -> 0 | N24: =SUM(N18:N21) -> 2 | O24: =SUM(O18:O21) -> 0 | ... AD24: =SUM(AD18:AD21) -> 1 | AF24: =SUM(AF18:AF21) -> 0 | AH24: =SUM(AH18:AH21) -> 0 | AI24: =SUM(AI18:AI21) -> 0 | AJ24: =SUM(AJ18:AJ21) -> 0 | AK24: =SUM(AK18:AK21) -> 0 | AL24: =SUM(AL18:AL21) -> 0 | AM24: =SUM(AM18:AM21) -> 0 | AN24: =SUM(AN18:AN21) -> 0 | AO24: =SUM(AO18:AO21) -> 0 | ... CB24: =SUM(CB18:CB21) -> 0
A26: 1 | B26: EASTERN | C26: ECG | D26: ABURI | E26: 5.873167 -0.157818 | F26: 2021 | G26: Outdoor | N26: 1 | V26: 2 | Z26: 1 | AB26: 1 | AG26: 1 | AV26: =SUM(AW26:BS26) -> 19 | BA26: 10 | BB26: 3 | BC26: 2 | BD26: 2 | BF26: 2 | BW26: 4 | BY26: 1
A27: 2 | B27: EASTERN | C27: ECG | D27: NKAWKAW | E27: 6.538083 -0.758909 | F27: 2022 | G27: Outdoor | N27: 1 | V27: 2 | Z27: 1 | AK27: 1 | AV27: =SUM(AW27:BS27) -> 11 | AW27: 1 | BA27: 2 | BC27: 1 | BD27: 2 | BF27: 2 | BJ27: 1 | BL27: 2 | BW27: 4 | BY27: 1
A28: 3 | B28: EASTERN | C28: ECG | D28: BUNSO | E28: 6.293186, -0.472517 | F28: 2023 | G28: Indoor | V28: 2 | Y28: 1 | AV28: =SUM(AW28:BS28) -> 4 | BK28: 2 | BL28: 2 | BX28: 2 | BZ28: 1
A29: 4 | B29: EASTERN | C29: ECG | D29: ASAMANKESE | E29: 5.857256 -0.661452 | F29: 2024 | G29: Outdoor | N29: 1 | AD29: 1 | AV29: =SUM(AW29:BS29) -> 2 | BJ29: 2
A30: 5 | B30: EASTERN | C30: ECG | D30: AKIM ODA | E30: 5.93694 -0.972932 | F30: 2024 | G30: Indoor | AD30: 1 | AV30: =SUM(AW30:BS30) -> 4 | AZ30: 1 | BA30: 1 | BK30: 2
A31: 6 | B31: EASTERN | C31: ECG | D31: SUHUM | E31: 6.027995 , -0.449935 | F31: 2022 | G31: Outdoor | N31: 1 | V31: 1 | Z31: 1 | AV31: =SUM(AW31:BS31) -> 7 | AW31: 1 | BA31: 1 | BD31: 1 | BJ31: 1 | BK31: 2 | BL31: 1 | BW31: 4 | BY31: 1
A32: 7 | B32: EASTERN | C32: ECG | D32: KOFORIDUA | E32: 6.091218 -0.258441 | F32: 2020 | G32: Outdoor | N32: 1 | V32: 2 | Y32: 1 | AN32: 1 | AV32: =SUM(AW32:BS32) -> 11 | AZ32: 1 | BA32: 3 | BD32: 7 | BW32: 4 | BY32: 1
A33: 8 | B33: EASTERN | C33: ECG | D33: KONONGO | E33: 6.624025 -1.2180472 | F33: 2024 | G33: Outdoor | N33: 1 | Z33: 1 | AV33: =SUM(AW33:BS33) -> 2 | BJ33: 1 | BK33: 1 | BU33: 1 | BW33: 4 | BZ33: 1 | CA33: 1
A34: 9 | B34: EASTERN | C34: ECG | D34: AKUSE | E34: 6.097085 0.064292 | F34: 2021 | G34: Outdoor | N34: 1 | V34: 2 | Z34: 1 | AP34: 1 | AV34: =SUM(AW34:BS34) -> 12 | BA34: 1 | BB34: 2 | BD34: 5 | BG34: 2 | BJ34: 1 | BK34: 1 | BV34: 1
B36: TOTAL | H36: =SUM(H26:H34) -> 0 | I36: =SUM(I26:I34) -> 0 | J36: =SUM(J26:J34) -> 0 | K36: =SUM(K26:K34) -> 0 | L36: =SUM(L26:L34) -> 0 | M36: =SUM(M26:M34) -> 0 | N36: =SUM(N26:N34) -> 7 | O36: =SUM(O26:O34) -> 0 | ... AD36: =SUM(AD26:AD34) -> 2 | AF36: =SUM(AF26:AF34) -> 0 | AG36: =SUM(AG26:AG34) -> 1 | AH36: =SUM(AH26:AH34) -> 0 | AI36: =SUM(AI26:AI34) -> 0 | AJ36: =SUM(AJ26:AJ34) -> 0 | AK36: =SUM(AK26:AK34) -> 1 | AL36: =SUM(AL26:AL34) -> 0 | AM36: =SUM(AM26:AM34) -> 0 | ... DJ36: =SUM(DJ26:DJ34) -> 0
A38: 1 | B38: GREATER ACCRA | C38: ECG | D38: CANTONMENT | E38: 5.584144 -0.164072 | F38: 2020 | G38: Indoor | R38: 2 | V38: 5 | Y38: 1 | Z38: 1 | AJ38: 1 | AK38: 1 | AL38: 1 | AM38: 2 | AP38: 1 | AR38: 1 | AS38: 1 | AT38: 2 | AU38: 1 | AV38: =SUM(AW38:BS38) -> 84 | AW38: 6 | BA38: 14 | BB38: 2 | BC38: 3 | BD38: 1 | BE38: 8 | BF38: 2 | BG38: 3 | BI38: 8 | BJ38: 9 | BK38: 1 | BS38: 27 | BX38: 8 | BY38: 1
A39: 2 | B39: GREATER ACCRA | C39: ECG | D39: MADINA | E39: 5.677437 -0.167211 | F39: 2020 | G39: Outdoor | N39: 1 | V39: 2 | Z39: 1 | AJ39: 1 | AO39: 1 | AV39: =SUM(AW39:BS39) -> 33 | AX39: 1 | BA39: 6 | BD39: 5 | BI39: 4 | BJ39: 7 | BS39: 10 | BX39: 4 | BY39: 1
A40: 3 | B40: GREATER ACCRA | C40: ECG | D40: RACK AFRICA DC | E40: 5.571390 -0.209692 | F40: 2020 | G40: Indoor | K40: 1 | V40: 3 | Z40: 1 | AK40: 1 | AP40: 1 | AV40: =SUM(AW40:BS40) -> 52 | AW40: 2 | AY40: 1 | AZ40: 3 | BA40: 21 | BC40: 2 | BD40: 3 | BE40: 2 | BF40: 1 | BG40: 10 | BH40: 1 | BI40: 2 | BJ40: 4
A41: 4 | B41: GREATER ACCRA | C41: ECG | D41: McCARTHY | E41: 5.563084 -0.299930 | F41: 2020 | G41: Outdoor | N41: 1 | V41: 2 | Z41: 1 | AJ41: 1 | AP41: 1 | AV41: =SUM(AW41:BS41) -> 43 | BA41: 10 | BB41: 2 | BC41: 3 | BD41: 3 | BE41: 2 | BJ41: 5 | BK41: 2 | BS41: 16 | BW41: 4 | BY41: 1
A42: 5 | B42: GREATER ACCRA | C42: ECG | D42: APOLONIA | E42: 5.804244 -0.091288 | F42: 2023 | G42: Indoor | AQ42: 1 | AV42: =SUM(AW42:BS42) -> 4 | AY42: 3 | BJ42: 1
A43: 6 | B43: GREATER ACCRA | C43: ECG | D43: GIL CITY CAMPUS | E43: 5.622542 -0.186943 | F43: 2022 | G43: Outdoor | N43: 1 | V43: 2 | Z43: 1 | AB43: 1 | AJ43: 1 | AV43: =SUM(AW43:BS43) -> 23 | AY43: 5 | BA43: 5 | BE43: 2 | BG43: 2 | BI43: 2 | BJ43: 2 | BS43: 5 | BW43: 4 | BY43: 1
A44: 7 | B44: GREATER ACCRA | C44: ECG | D44: TEMA FREEZONES | E44: 5.693232 0.006872 | F44: 2020 | G44: Indoor | R44: 1 | V44: 3 | Z44: 1 | AJ44: 1 | AP44: 1 | AV44: =SUM(AW44:BS44) -> 44 | AW44: 2 | AY44: 1 | BA44: 13 | BB44: 3 | BC44: 1 | BE44: 4 | BI44: 2 | BJ44: 6 | BS44: 12 | BX44: 4 | BY44: 1
A45: 8 | B45: GREATER ACCRA | C45: ECG | D45: ETIX(ONIX DC) | E45: 5.766104 -0.110246 | F45: 2021 | G45: Indoor | R45: 1 | V45: 1 | Z45: 1 | AI45: 1 | AN45: 1 | AV45: =SUM(AW45:BS45) -> 32 | AZ45: 1 | BA45: 5 | BB45: 2 | BD45: 8 | BE45: 2 | BG45: 2 | BI45: 3 | BJ45: 2 | BK45: 1 | BS45: 6
A46: 9 | B46: GREATER ACCRA | C46: ECG | D46: GIJ DZORWULU | E46: 5.622542 -0.186943 | F46: 2021 | G46: Indoor | L46: 1 | T46: 1 | Z46: 1 | AH46: 1 | AV46: =SUM(AW46:BS46) -> 14 | AY46: 1 | BA46: 2 | BE46: 2 | BJ46: 3 | BS46: 6 | BW46: 4 | BY46: 1
A47: 10 | B47: GREATER ACCRA | C47: ECG | D47: NUNGUA | E47: 5.614282 -0.089064 | F47: 2020 | G47: Outdoor | N47: 1 | V47: 1 | Z47: 1 | AC47: 1 | AJ47: 1 | AV47: =SUM(AW47:BS47) -> 23 | BA47: 6 | BC47: 2 | BG47: 4 | BH47: 1 | BI47: 2 | BJ47: 1 | BS47: 7 | BW47: 4 | BY47: 1
A48: 11 | B48: GREATER ACCRA | C48: ECG | D48: AMASAMAN | E48: 5.704165 , -0.300260 | F48: 2021 | G48: Outdoor | N48: 1 | V48: 1 | Z48: 1 | AN48: 1 | AV48: =SUM(AW48:BS48) -> 26 | BA48: 18 | BB48: 1 | BD48: 2 | BE48: 2 | BJ48: 3 | BV48: 1 | BW48: 4 | BY48: 1
A49: 12 | B49: GREATER ACCRA | C49: ECG | D49: DAWHENYA | E49: 5.757568 0.083992 | F49: 2021 | G49: Indoor | O49: 1 | V49: 1 | Z49: 1 | AB49: 1 | AF49: 1 | AG49: 1 | AV49: =SUM(AW49:BS49) -> 22 | BA49: 17 | BB49: 1 | BC49: 1 | BI49: 1 | BN49: 2 | BU49: 1 | BV49: 1 | BX49: 4 | BY49: 1
A50: 13 | B50: GREATER ACCRA | C50: ECG | D50: DAWA | E50: 5.869013 0.263467 | F50: 2020 | G50: Indoor | V50: 1 | Z50: 1 | AK50: 1 | AV50: =SUM(AW50:BS50) -> 14 | BA50: 3 | BB50: 2 | BD50: 4 | BJ50: 3 | BK50: 2
...

Sheet MASTER-BACKHAUL
B1: Region | C1: TERRITORY | D1: Name of Line | E1: Coordinates A-End | F1: Coordinates B-End | G1: Fiber Count | H1: Distance (m) | I1: SFP(10gig) Distance(km) | J1: OPGW / UGFOC /ADSS Status | K1: Age | L1: Cost/Value | M1: Comment | N1: Status | O1: Passed Commisioning Tests | P1: Total New Poles | Q1: New 9m Poles | R1: New 11m Poles | S1: Coordinates 1 | T1: Coordinates 2 | U1: Coordinates 3 | V1: Coordinates 4 | W1: Coordinates 5 | X1: Coordinates 6 | Y1: Coordinates 7 | Z1: Coordinates 8 | AA1: Coordinates 9 | AB1: Coordinates 10 | AC1: Coordinates 11 | AD1: Coordinates 12 | AE1: Coordinates 13 | AF1: Coordinates 14 | AG1: Coordinates 15 | AH1: Coordinates 16 | AI1: Coordinates 17 | AJ1: Coordinates 18 | AK1: Coordinates 19 | AL1: Coordinates 20 | AM1: Coordinates 21 | AN1: Coordinates 22 | AO1: Coordinates 23 | AP1: Coordinates 24 | AQ1: Coordinates 25 | AR1: Coordinates 26 | AS1: Coordinates 27 | AT1: Coordinates 28 | AU1: Coordinates 29 | AV1: Coordinates 30 | AW1: Coordinates 31 | AX1: Coordinates 32 | AY1: Coordinates 33 | AZ1: Coordinates 34 | BA1: Coordinates 35 | BB1: Coordinates 36 | BC1: Coordinates 37 | BD1: Coordinates 38 | BE1: Coordinates 39 | BF1: Coordinates 40 | BG1: Coordinates 41 | BH1: Coordinates 42 | BI1: Coordinates 43 | BJ1: Coordinates 44 | BK1: Coordinates 45 | BL1: Coordinates 46 | BM1: Coordinates 47 | BN1: Coordinates 48 | BO1: Coordinates 49 | BP1: Coordinates 50 | BQ1: Coordinates 51 | BR1: Coordinates 52 | BS1: Coordinates 53 | BT1: Coordinates 54 | BU1: Coordinates 55 | BV1: Coordinates 56 | BW1: Coordinates 57 | BX1: Coordinates 58 | BY1: Coordinates 59 | BZ1: Coordinates 60 | CA1: Coordinates 61 | CB1: Coordinates 62 | CC1: Coordinates 63 | CD1: Coordinates 64 | CE1: Coordinates 65 | CF1: Coordinates 66 | CG1: Coordinates 67 | CH1: Coordinates 68 | CI1: Coordinates 69 | CJ1: Coordinates 70 | CK1: Coordinates 71 | CL1: Coordinates 72 | CM1: Coordinates 73 | CN1: Coordinates 74 | CO1: Coordinates 75
A2: 1 | B2: GREATER ACCRA | C2: ECG | D2: Tema - Dawa | E2: 5.693232, 0.006872 | F2: 5.869013, 0.263467 | G2: 48 | H2: 44000 | I2: 60 | J2: ADSS | K2: 2017 | N2: Active
A3: 2 | B3: GREATER ACCRA | C3: ECG | D3: Dawa - Ada | E3: 5.869013, 0.263467 | F3: 5.893987, 0.503603 | G3: 48 | H3: 53300 | I3: 80 | J3: ADSS | K3: 2017 | N3: Active
A4: 3 | B4: VOLTA | C4: ECG | D4: Ada - Sogakope | E4: 5.893987 0.503603 | F4: 5.997086 0.595473 | G4: 48 | H4: 27000 | I4: 60 | J4: ADSS | K4: 2017 | N4: Active
A5: 4 | B5: EASTERN | C5: ECG | D5: Akuse-Tema | E5: 6.097085, 0.064292 | F5: 5.693232, 0.006872 | G5: 48 | H5: 54400 | I5: 60 | J5: ADSS | K5: 2018 | N5: Active | O5: Yes
A6: 5 | B6: GREATER ACCRA | C6: ECG | D6: RackAfrica - Cantoment (Sec) | E6: 5.571440, -0.209714 | F6: 5.584144, -0.164072 | G6: 48 | H6: 18500 | I6: 40 | J6: ADSS | K6: 2019 | N6: Active
A7: 6 | B7: GREATER ACCRA | C7: ECG | D7: Cantoment - Tema | E7: 5.584144, -0.164072 | F7: 5.693232, 0.006872 | G7: 48 | H7: 43000 | I7: 60 | J7: ADSS | K7: 2019 | N7: Active
A8: 7 | B8: GREATER ACCRA | C8: ECG | D8: Nungua - Cantoment | E8: 5.614282 -0.089064 | F8: 5.584144, -0.164072 | G8: 48 | H8: 2800 | I8: 40 | J8: ADSS | K8: 2019 | N8: Active
A9: 8 | B9: ASHANTI | C9: ECG | D9: Asanteman - Roman Hill (Sofoline Leg) | E9: 5.704165, -0.300260 | F9: 6.696086, -1.617477 | G9: 48 | H9: 17000 | I9: 60 | J9: ADSS | K9: 2020 | N9: Active | O9: Yes
A10: 9 | B10: ASHANTI | C10: ECG | D10: Asanteman - Roman Hill (Serwaa Nyarko Leg) | E10: 5.704165, -0.300260 | F10: 6.696086, -1.617477 | G10: 48 | H10: 15500 | I10: 60 | J10: ADSS | K10: 2020 | N10: Active | O10: Yes
A11: 10 | B11: EASTERN | C11: ECG | D11: Akosombo- Akuse | E11: 6.297273, 0.055737 | F11: 6.097085, 0.064292 | G11: 48 | H11: 26000 | J11: ADSS | K11: 2020 | N11: Active
A12: 11 | B12: GREATER ACCRA | C12: ECG | D12: Tema - Prampram | E12: 5.693232, 0.006872 | F12: 5.757568, 0.083992 | G12: 48 | H12: 4400 | I12: 40 | J12: ADSS | K12: 2020 | N12: Active
A13: 12 | B13: GREATER ACCRA | C13: ECG | D13: Etix - Madina | E13: 5.766104 -0.110246 | F13: 5.677437 -0.167211 | G13: 48 | H13: 21000 | I13: 40 | J13: ADSS | K13: 2020 | N13: Active
A14: 13 | B14: GREATER ACCRA | C14: ECG | D14: Madina - GIJ | E14: 5.677437 -0.167211 | F14: 5.622542 -0.186943 | G14: 48 | H14: 26000 | I14: 60 | J14: ADSS | K14: 2020 | N14: Active
A15: 14 | B15: GREATER ACCRA | C15: ECG | D15: Madina-Cantoment | E15: 5.677437 -0.167211 | F15: 5.584144, -0.164072 | G15: 48 | H15: 26000 | I15: 60 | J15: ADSS | K15: 2020 | N15: Active
A16: 15 | B16: GREATER ACCRA | C16: ECG | D16: Madina - RackAfrica | E16: 5.677437 -0.167211 | F16: 5.571440 -0.209714 | G16: 48 | H16: 0 | I16: 60 | J16: ADSS | K16: 2020 | N16: Active
A17: 16 | B17: GREATER ACCRA | C17: ECG | D17: GIJ - Cantoment | E17: 5.622542 -0.186943 | F17: 5.584144, -0.164072 | G17: 48 | H17: 8100 | I17: 60 | J17: ADSS | K17: 2020 | N17: Active
A18: 17 | B18: ASHANTI | C18: ECG | D18: Kubease(Konongo)-Roman Hill | E18: 6.675194, -1.380315 | F18: 6.708774, -1.627550 | G18: 48 | H18: 50000 | I18: 80 | J18: ADSS | K18: 2021 | N18: Active
A19: 18 | B19: ASHANTI | C19: ECG | D19: Asanteman - BroadSpectrum | E19: 5.704165, -0.300260 | F19: 4.960283, -1.736001 | G19: 48 | H19: 3500 | I19: 20 | J19: ADSS | K19: 2021 | N19: Active | O19: Yes
A20: 19 | B20: CENTRAL | C20: ECG | D20: Winneba - McCarthy | E20: 5.379158, -0.652166 | F20: 5.563084, -0.299930 | G20: 48 | H20: 61000 | I20: 80 | J20: ADSS | K20: 2021 | N20: Active | O20: Yes
A21: 20 | B21: EASTERN | C21: ECG | D21: Amasaman- Suhum | E21: 5.704165,-0.300260 | F21: 6.027995, -0.449935 | G21: 48 | H21: 6000 | I21: 60 | J21: ADSS | K21: 2021 | N21: Active
A22: 21 | B22: EASTERN | C22: ECG | D22: Suhum- Nkawkaw | E22: 6.027995 -0.449935 | F22: 6.538083 -0.758909 | G22: 48 | H22: 96000 | I22: 80 | J22: ADSS | K22: 2021 | N22: Active
A23: 22 | B23: EASTERN | C23: ECG | D23: Nkawkaw - Kubease(Konongo) | E23: 6.538083, -0.758909 | F23: 6.675194, -1.380315 | G23: 48 | H23: 87000 | I23: 100 | J23: ADSS | K23: 2021 | N23: Active
A24: 23 | B24: EASTERN | C24: ECG | D24: Akuse - Etix | E24: 6.097085, 0.064292 | F24: 5.766104, -0.110246 | G24: 48 | H24: 75000 | I24: 80 | J24: ADSS | K24: 2021 | N24: Active
A25: 24 | B25: EASTERN | C25: ECG | D25: Madina - Aburi | E25: 5.677437, -0.167211 | F25: 5.873167, -0.157818 | G25: 48 | H25: 35000 | I25: 60 | J25: ADSS | K25: 2021 | N25: Active | O25: Yes
A26: 25 | B26: GREATER ACCRA | C26: ECG | D26: McCarthy - RackAfrica | E26: 5.563084, -0.299930 | F26: 5.571440, -0.209714 | G26: 48 | H26: 20000 | I26: 60 | J26: ADSS | K26: 2021 | N26: Active
A27: 26 | B27: GREATER ACCRA | C27: ECG | D27: RackAfrica - Cantoment (Prim) | E27: 5.571440, -0.209714 | F27: 5.584144, -0.164072 | G27: 48 | H27: 4500 | I27: 40 | J27: ADSS | K27: 2021 | N27: Active
A28: 27 | B28: GREATER ACCRA | C28: ECG | D28: Etix - Tema | E28: 5.766104, -0.110246 | F28: 5.693232, 0.006872 | G28: 48 | H28: 28000 | I28: 60 | J28: ADSS | K28: 2021 | N28: Active
A29: 28 | B29: GREATER ACCRA | C29: ECG | D29: Madina - Amasaman | E29: 5.677437 -0.167211 | F29: 5.704159 -0.300296 | G29: 48 | H29: 12700 | I29: 60 | J29: ADSS | K29: 2021 | N29: Active
A30: 29 | B30: GREATER ACCRA | C30: ECG | D30: Cantoment - MCcarthy | E30: 5.584144, -0.164072 | F30: 5.563084 -0.299930 | G30: 48 | H30: 26500 | I30: 80 | J30: ADSS | K30: 2021 | N30: Active
A31: 30 | B31: GREATER ACCRA | C31: ECG | D31: McCarthy - Madina | E31: 5.563084, -0.299930 | F31: 5.677437 -0.167211 | G31: 48 | H31: 22000 | I31: 60 | J31: ADSS | K31: 2021 | N31: Active
A32: 31 | B32: VOLTA | C32: ECG | D32: Ho-Juapong | E32: 6.571861 0.406850 | F32: 6.250124 0.137610 | G32: 48 | H32: 72529.8 | J32: ADSS | K32: 2021 | N32: Active
A33: 32 | B33: ASHANTI | C33: ECG | D33: Roman Hill - Obuasi | E33: 6.696086, -1.617477 | F33: 6.204062, -1.677247 | G33: 48 | H33: 76000 | I33: 80 | J33: ADSS | K33: 2022 | N33: Active
A34: 33 | B34: CENTRAL | C34: ECG | D34: CapeCoast-Winneba | E34: 5.117613, -1.244324 | F34: 5.379158, -0.652166 | G34: 48 | H34: 89000 | I34: 80 | J34: ADSS | K34: 2022 | N34: Active | O34: Yes
A35: 34 | B35: GREATER ACCRA | C35: ECG | D35: McCarthy - Amasaman | E35: 5.563084, -0.299930 | F35: 5.704165, -0.300260 | G35: 48 | H35: 59000 | I35: 60 | J35: ADSS | K35: 2022 | N35: Active | O35: Yes
A36: 35 | B36: GREATER ACCRA | C36: ECG | D36: Cantonment-GIL | E36: 5.584144, -0.164072 | F36: 5.622542 -0.186943 | G36: 48 | H36: 17000 | I36: 60 | J36: ADSS | K36: 2022 | N36: Active
A37: 36 | B37: GREATER ACCRA | C37: ECG | D37: Nungua - Tema | E37: 5.614282 -0.089064 | F37: 5.693232 0.006872 | G37: 48 | H37: 3000 | I37: 60 | J37: ADSS | K37: 2022 | N37: Active
A38: 37 | B38: VOLTA | C38: ECG | D38: Sogakope-Akatsi | E38: 5.997086 0.595473 | F38: 6.127324 0.802253 | G38: 48 | H38: 30000 | I38: 60 | J38: ADSS | K38: 2022 | N38: Active
A39: 38 | B39: VOLTA | C39: ECG | D39: Akatsi-Aflao | E39: 6.127324 0.802253 | F39: 6.117796 1.190115 | G39: 48 | H39: 55000 | I39: 80 | J39: ADSS | K39: 2022 | N39: Active
A40: 39 | B40: WESTERN | C40: ECG | D40: Obuasi - Wasa Akropong | E40: 6.204062 -1.677247 | F40: 5.311207 -1.992372 | G40: 48 | H40: 82000 | I40: 120 | J40: ADSS | K40: 2022 | N40: Active
...

Sheet MASTER-ACCESSORIES - BACKHAUL
A1: S/N | B1: Region | C1: Territory | D1: Name of Line | E1: Distance (m) | F1: Pole Brackets (pcs) | G1: Tension Clamps (pcs) | H1: Suspensions (pcs) | I1: Buckles (pcs) | J1: Steel Band (m) | K1: Closures (pcs) | L1: Status
A2: 1 | B2: ASHANTI | C2: ECG | D2: Kubease(Konongo)-Roman Hill | E2: 50000 | F2: =(((E2/70)+1)*0.4) -> 286.11429 | G2: =2*F2 -> 572.22857 | H2: =(((E2/70)+1)*0.6) -> 429.17143 | I2: =H2+F2 -> 715.28571 | J2: =I2 -> 715.28571 | K2: =(E2/4000)+1 -> 13.5 | L2: Active
A3: 2 | B3: ASHANTI | C3: ECG | D3: Asanteman - Roman Hill (Sofoline Leg) | E3: 17000 | F3: =(((E3/70)+1)*0.4) -> 97.542857 | G3: =2*F3 -> 195.08571 | H3: =(((E3/70)+1)*0.6) -> 146.31429 | I3: =H3+F3 -> 243.85714 | J3: =I3 -> 243.85714 | K3: =(E3/4000)+1 -> 5.25 | L3: Active
A4: 3 | B4: ASHANTI | C4: ECG | D4: Asanteman - Roman Hill (Serwaa Nyarko Leg) | E4: 15500 | F4: =(((E4/70)+1)*0.4) -> 88.971429 | G4: =2*F4 -> 177.94286 | H4: =(((E4/70)+1)*0.6) -> 133.45714 | I4: =H4+F4 -> 222.42857 | J4: =I4 -> 222.42857 | K4: =(E4/4000)+1 -> 4.875 | L4: Active
A5: 4 | B5: ASHANTI | C5: ECG | D5: Asanteman - BroadSpectrum | E5: 3500 | F5: =(((E5/70)+1)*0.4) -> 20.4 | G5: =2*F5 -> 40.8 | H5: =(((E5/70)+1)*0.6) -> 30.6 | I5: =H5+F5 -> 51 | J5: =I5 -> 51 | K5: =(E5/4000)+1 -> 1.875 | L5: Active
A6: 5 | B6: ASHANTI | C6: ECG | D6: Roman Hill - Obuasi | E6: 76000 | F6: =(((E6/70)+1)*0.4) -> 434.68571 | G6: =2*F6 -> 869.37143 | H6: =(((E6/70)+1)*0.6) -> 652.02857 | I6: =H6+F6 -> 1086.7143 | J6: =I6 -> 1086.7143 | K6: =(E6/4000)+1 -> 20 | L6: Active
A7: 6 | B7: ASHANTI | C7: ECG | D7: Asanteman - Bechem (Mankranso) | E7: 35000 | F7: =(((E7/70)+1)*0.4) -> 200.4 | G7: =2*F7 -> 400.8 | H7: =(((E7/70)+1)*0.6) -> 300.6 | I7: =H7+F7 -> 501 | J7: =I7 -> 501 | K7: =(E7/4000)+1 -> 9.75 | L7: Active
A8: 7 | B8: AHAFO | C8: NEDCO | D8: Asanteman (Mankranso) - Bechem | E8: 40000 | F8: =(((E8/70)+1)*0.4) -> 228.97143 | G8: =2*F8 -> 457.94286 | H8: =(((E8/70)+1)*0.6) -> 343.45714 | I8: =H8+F8 -> 572.42857 | J8: =I8 -> 572.42857 | K8: =(E8/4000)+1 -> 11 | L8: Active
A9: 8 | B9: ASHANTI | C9: ECG | D9: Abofour - Kumasi ECG | E9: 67000 | F9: =(((E9/70)+1)*0.4) -> 383.25714 | G9: =2*F9 -> 766.51429 | H9: =(((E9/70)+1)*0.6) -> 574.88571 | I9: =H9+F9 -> 958.14286 | J9: =I9 -> 958.14286 | K9: =(E9/4000)+1 -> 17.75 | L9: Active
A10: 9 | B10: BONO EAST | C10: NEDCO | D10: Abofour - Kumasi NEDCO | E10: 5000 | F10: =(((E10/70)+1)*0.4) -> 28.971429 | G10: =2*F10 -> 57.942857 | H10: =(((E10/70)+1)*0.6) -> 43.457143 | I10: =H10+F10 -> 72.428571 | J10: =I10 -> 72.428571 | K10: =(E10/4000)+1 -> 2.25 | L10: Active
A11: 10 | B11: BONO EAST | C11: NEDCO | D11: Abofour - Techiman | E11: 77000 | F11: =(((E11/70)+1)*0.4) -> 440.4 | G11: =2*F11 -> 880.8 | H11: =(((E11/70)+1)*0.6) -> 660.6 | I11: =H11+F11 -> 1101 | J11: =I11 -> 1101 | K11: =(E11/4000)+1 -> 20.25 | L11: Active
A12: 11 | B12: ASHANTI | C12: ECG | D12: Kumasi - Nkawie | E12: 15000 | F12: =(((E12/70)+1)*0.4) -> 86.114286 | G12: =2*F12 -> 172.22857 | H12: =(((E12/70)+1)*0.6) -> 129.17143 | I12: =H12+F12 -> 215.28571 | J12: =I12 -> 215.28571 | K12: =(E12/4000)+1 -> 4.75 | L12: Active
A13: 12 | B13: ASHANTI | C13: ECG | D13: Nkawie - Bibiani | E13: 73000 | F13: =(((E13/70)+1)*0.4) -> 417.54286 | G13: =2*F13 -> 835.08571 | H13: =(((E13/70)+1)*0.6) -> 626.31429 | I13: =H13+F13 -> 1043.8571 | J13: =I13 -> 1043.8571 | K13: =(E13/4000)+1 -> 19.25 | L13: Active
... A102: 101 | B102: NORTHERN | C102: NEDCO | D102: Bimbilla - Yendi | E102: 75000 | F102: =(((E102/70)+1)*0.4) -> 428.97143 | G102: =2*F102 -> 857.94286 | H102: =(((E102/70)+1)*0.6) -> 643.45714 | I102: =H102+F102 -> 1072.4286 | J102: =I102 -> 1072.4286 | K102: =(E102/4000)+1 -> 19.75 | L102: Active
D112: TOTAL | E112: =SUM(E2:E102) -> 5127736.8 | F112: =SUM(F2:F102) -> 29341.753 | G112: =SUM(G2:G102) -> 58683.506 | H112: =SUM(H2:H102) -> 44012.63 | I112: =SUM(I2:I102) -> 73354.383 | J112: =SUM(J2:J102) -> 73354.383 | K112: =SUM(K2:K102) -> 1382.9342
D138: LEGEND:
D140: ODF:- Optical Distribution Frames
D142: ADSS FOC:- All Dielectric Self Supporting Fibre Optic Cable

Sheet MASTER-METRO
B1: REGION | C1: TERRITOY | D1: NAME OF LINE | E1: COORDINATES A-END | F1: COORDINATES B-END | G1: FIBER COUNT | H1: LOCATION | I1: Drop Cable Distance (M) | J1: ADSS DISTANCE (M) | K1: 1G SFP DISTANCE(KM) | L1: 10G SFP DISTANCE(KM) | M1: CPE | N1: OPGW / UGFOC /ADSS STATUS | O1: AGE | P1: DATE | Q1: MONTH | R1: COST/VALUE | S1: STATUS | T1: Passed Commisioning Tests | U1: Total New Poles | V1: 9m Poles | W1: 11m Poles | X1: Coordinate 1 | Y1: Coordinate 2 | Z1: Coordinate 3 | AA1: Coordinate 4 | AB1: Coordinate 5 | AC1: Coordinate 6 | AD1: Coordinate 7 | AE1: Coordinate 8 | AF1: Coordinate 9 | AG1: Coordinate 10 | AH1: Coordinate 11 | AI1: Coordinate 12 | AJ1: Coordinate 13 | AK1: Coordinate 14 | AL1: Coordinate 15 | AM1: Coordinate 16 | AN1: Coordinate 17 | AO1: Coordinate 18 | AP1: Coordinate 19 | AQ1: Coordinate 20 | AR1: Coordinate 21 | AS1: Coordinate 22 | AT1: Coordinate 23 | AU1: Coordinate 24 | AV1: Coordinate 25 | AW1: Coordinate 26 | AX1: Coordinate 27 | AY1: Coordinate 28 | AZ1: Coordinate 29 | BA1: Coordinate 30 | BB1: Coordinate 31 | BC1: Coordinate 32 | BD1: Coordinate 33 | BE1: Coordinate 34 | BF1: Coordinate 35 | BG1: Coordinate 36 | BH1: Coordinate 37 | BI1: Coordinate 38 | BJ1: Coordinate 39 | BK1: Coordinate 40 | BL1: Coordinate 41 | BM1: Coordinate 42 | BN1: Coordinate 43 | BO1: Coordinate 44 | BP1: Coordinate 45 | BQ1: Coordinate 46 | BR1: Coordinate 47 | BS1: Coordinate 48 | BT1: Coordinate 49 | BU1: Coordinate 50 | BV1: Coordinate 51 | BW1: Coordinate 52 | BX1: Coordinate 53 | BY1: Coordinate 54 | BZ1: Coordinate 55 | CA1: Coordinate 56 | CB1: Coordinate 57 | CC1: Coordinate 58 | CD1: Coordinate 59 | CE1: Coordinate 60 | CF1: Coordinate 61 | CG1: Coordinate 62 | CH1: Coordinate 63 | CI1: Coordinate 64 | CJ1: Coordinate 65 | CK1: Coordinate 66 | CL1: Coordinate 67 | CM1: Coordinate 68
A2: {=_xlfn.SEQUENCE(COUNTA(D$2:D$1048576))} -> 1 | B2: ASHANTI | C2: ECG | D2: MANHYIA PALACE | E2: 6.703436,-1.614345 | F2: 6.708775, -1.627550 | G2: {=_xlfn.IFS(J2<301,2,J2>300,48)} -> 48 | H2: KUMASI | I2: 0 | J2: 2100 | K2: =IF(M2="ONT",20,IF(M2="N/A","N/A",IF(M2="MIKROTIK",IF(J2<3000,10,IF(3000<J2>10000,20,IF(10000<J2>20000,40,IF(20000<J2>40000,60,IF(J2>40000,80,IF(J2<300,3,))))))))) -> FALSE | M2: Furukawa | N2: ADSS | O2: 2021 | S2: ACTIVE | T2: Yes
A3: 2 | B3: ASHANTI | C3: ECG | D3: PRINCE OF PEACE GIRLS | E3: 6.69596,-1.64277 | F3: 6.708775, -1.627550 | G3: {=_xlfn.IFS(J3<301,2,J3>300,48)} -> 48 | H3: KUMASI | I3: 0 | J3: 2200 | K3: =IF(M3="ONT",20,IF(M3="N/A","N/A",IF(M3="MIKROTIK",IF(J3<3000,10,IF(3000<J3>10000,20,IF(10000<J3>20000,40,IF(20000<J3>40000,60,IF(J3>40000,80,IF(J3<300,3,))))))))) -> N/A | M3: N/A | N3: ADSS | O3: 2020 | S3: INACTIVE | T3: Yes
A4: 3 | B4: ASHANTI | C4: ECG | D4: ST. LOUIS SENIOR HIGH, KUMASI | E4: 6.695041,-1.545178 | F4: 6.708775, -1.627550 | G4: {=_xlfn.IFS(J4<301,2,J4>300,48)} -> 48 | H4: KUMASI | I4: 0 | J4: 1500 | K4: =IF(M4="ONT",20,IF(M4="N/A","N/A",IF(M4="MIKROTIK",IF(J4<3000,10,IF(3000<J4>10000,20,IF(10000<J4>20000,40,IF(20000<J4>40000,60,IF(J4>40000,80,IF(J4<300,3,))))))))) -> FALSE | M4: Furukawa | N4: ADSS | O4: 2020 | S4: ACTIVE | T4: Yes
A5: 4 | B5: ASHANTI | C5: ECG | D5: ADVENTIST SENIOR HIGH, KUMASI | E5: 6.70934,-1.632254 | F5: 6.708775, -1.627550 | G5: {=_xlfn.IFS(J5<301,2,J5>300,48)} -> 2 | H5: KUMASI | I5: 150 | J5: 0 | K5: =IF(M5="ONT",20,IF(M5="N/A","N/A",IF(M5="MIKROTIK",IF(J5<3000,10,IF(3000<J5>10000,20,IF(10000<J5>20000,40,IF(20000<J5>40000,60,IF(J5>40000,80,IF(J5<300,3,))))))))) -> FALSE | M5: Furukawa | N5: ADSS | O5: 2020 | S5: ACTIVE | T5: Yes
A6: 5 | B6: ASHANTI | C6: ECG | D6: AGRIC NZEMA SENIOR HIGH, KUMASI | E6: 6.67339,-1.67716 | F6: 6.696086°, -1.617477° | G6: {=_xlfn.IFS(J6<301,2,J6>300,48)} -> 48 | H6: KUMASI | I6: 0 | J6: 3575 | K6: =IF(M6="ONT",20,IF(M6="N/A","N/A",IF(M6="MIKROTIK",IF(J6<3000,10,IF(3000<J6>10000,20,IF(10000<J6>20000,40,IF(20000<J6>40000,60,IF(J6>40000,80,IF(J6<300,3,))))))))) -> FALSE | M6: Furukawa | N6: ADSS | O6: 2020 | S6: ACTIVE | T6: Yes
A7: 6 | B7: ASHANTI | C7: ECG | D7: AL-AZARIYA ISLAMIC SNR. HIGH, KUMASI | E7: 6.73497,-1.608583 | F7: 6.708775, -1.627550 | G7: {=_xlfn.IFS(J7<301,2,J7>300,48)} -> 48 | H7: KUMASI | I7: 0 | J7: 800 | K7: =IF(M7="ONT",20,IF(M7="N/A","N/A",IF(M7="MIKROTIK",IF(J7<3000,10,IF(3000<J7>10000,20,IF(10000<J7>20000,40,IF(20000<J7>40000,60,IF(J7>40000,80,IF(J7<300,3,))))))))) -> FALSE | M7: Furukawa | N7: ADSS | O7: 2020 | S7: ACTIVE | T7: Yes
A8: 7 | B8: ASHANTI | C8: ECG | D8: ANGLICAN SENIOR HIGH, KUMASI | E8: 6.692,-1.60927 | F8: 6.696086°, -1.617477° | G8: {=_xlfn.IFS(J8<301,2,J8>300,48)} -> 48 | H8: KUMASI | I8: 0 | J8: 400 | K8: =IF(M8="ONT",20,IF(M8="N/A","N/A",IF(M8="MIKROTIK",IF(J8<3000,10,IF(3000<J8>10000,20,IF(10000<J8>20000,40,IF(20000<J8>40000,60,IF(J8>40000,80,IF(J8<300,3,))))))))) -> FALSE | M8: Furukawa | N8: ADSS | O8: 2020 | S8: ACTIVE | T8: Yes
A9: 8 | B9: ASHANTI | C9: ECG | D9: ARMED FORCES SENIOR HIGH/TECH, KUMASI | E9: 6.691597,-1.629728 | F9: 6.696086°, -1.617477° | G9: {=_xlfn.IFS(J9<301,2,J9>300,48)} -> 48 | H9: KUMASI | I9: 0 | J9: 1200 | K9: =IF(M9="ONT",20,IF(M9="N/A","N/A",IF(M9="MIKROTIK",IF(J9<3000,10,IF(3000<J9>10000,20,IF(10000<J9>20000,40,IF(20000<J9>40000,60,IF(J9>40000,80,IF(J9<300,3,))))))))) -> FALSE | M9: Furukawa | N9: ADSS | O9: 2020 | S9: ACTIVE | T9: Yes
A10: 9 | B10: ASHANTI | C10: ECG | D10: ASANTEMAN SENIOR HIGH | E10: 6.708825,-1.627581 | F10: 6.708775, -1.627550 | G10: {=_xlfn.IFS(J10<301,2,J10>300,48)} -> 48 | H10: KUMASI | I10: 0 | J10: 500 | K10: =IF(M10="ONT",20,IF(M10="N/A","N/A",IF(M10="MIKROTIK",IF(J10<3000,10,IF(3000<J10>10000,20,IF(10000<J10>20000,40,IF(20000<J10>40000,60,IF(J10>40000,80,IF(J10<300,3,))))))))) -> FALSE | M10: Furukawa | N10: ADSS | O10: 2020 | S10: ACTIVE | T10: Yes
A11: 10 | B11: ASHANTI | C11: ECG | D11: ASOKORE MAMPONG MUNICIPAL | E11: 6.7175,-1.56237 | F11: 6.696086°, -1.617477° | G11: {=_xlfn.IFS(J11<301,2,J11>300,48)} -> 48 | H11: ASOKORE | I11: 0 | J11: 426 | K11: =IF(M11="ONT",20,IF(M11="N/A","N/A",IF(M11="MIKROTIK",IF(J11<3000,10,IF(3000<J11>10000,20,IF(10000<J11>20000,40,IF(20000<J11>40000,60,IF(J11>40000,80,IF(J11<300,3,))))))))) -> FALSE | M11: Furukawa | N11: ADSS | O11: 2020 | S11: ACTIVE | T11: Yes
A12: 11 | B12: ASHANTI | C12: ECG | D12: EJISUMAN SENIOR HIGH | E12: 6.728703,-1.475162 | F12: 6.696086°, -1.617477° | G12: {=_xlfn.IFS(J12<301,2,J12>300,48)} -> 48 | H12: EJISU | I12: 0 | J12: 2500 | K12: =IF(M12="ONT",20,IF(M12="N/A","N/A",IF(M12="MIKROTIK",IF(J12<3000,10,IF(3000<J12>10000,20,IF(10000<J12>20000,40,IF(20000<J12>40000,60,IF(J12>40000,80,IF(J12<300,3,))))))))) -> N/A | M12: N/A | N12: ADSS | O12: 2020 | S12: ACTIVE | T12: Yes
A13: 12 | B13: ASHANTI | C13: ECG | D13: ISLAMIC SENIOR HIGH, AMPABAME | E13: 6.712857,-1.641135 | F13: 6.708775, -1.627550 | G13: {=_xlfn.IFS(J13<301,2,J13>300,48)} -> 48 | H13: KUMASI | I13: 0 | J13: 1100 | K13: =IF(M13="ONT",20,IF(M13="N/A","N/A",IF(M13="MIKROTIK",IF(J13<3000,10,IF(3000<J13>10000,20,IF(10000<J13>20000,40,IF(20000<J13>40000,60,IF(J13>40000,80,IF(J13<300,3,))))))))) -> FALSE | M13: Furukawa | N13: ADSS | O13: 2020 | S13: ACTIVE | T13: Yes
A14: 13 | B14: ASHANTI | C14: ECG | D14: KNUST SENIOR HIGH | E14: 6.689783,-1.54805 | F14: 6.696086°, -1.617477° | G14: {=_xlfn.IFS(J14<301,2,J14>300,48)} -> 48 | H14: KUMASI | I14: 0 | J14: 629 | K14: =IF(M14="ONT",20,IF(M14="N/A","N/A",IF(M14="MIKROTIK",IF(J14<3000,10,IF(3000<J14>10000,20,IF(10000<J14>20000,40,IF(20000<J14>40000,60,IF(J14>40000,80,IF(J14<300,3,))))))))) -> FALSE | M14: Furukawa | N14: ADSS | O14: 2020 | S14: ACTIVE | T14: Yes
... A54: 53 | B54: ASHANTI | C54: ECG | D54: EFANEST KESSBEN CEO RESIDENCE KUMASI | E54: 6.683168, -1.632282 | F54: 6.696086°, -1.617477° | G54: {=_xlfn.IFS(J54<301,2,J54>300,48)} -> 48 | H54: KUMASI | I54: 0 | J54: 1700 | K54: =IF(M54="ONT",20,IF(M54="N/A","N/A",IF(M54="MIKROTIK",IF(J54<3000,10,IF(3000<J54>10000,20,IF(10000<J54>20000,40,IF(20000<J54>40000,60,IF(J54>40000,80,IF(J54<300,3,))))))))) -> 20 | M54: ONT | N54: ADSS | O54: 2021 | S54: ACTIVE | T54: Yes
A55: 54 | B55: ASHANTI | C55: ECG | D55: ODENEHO KUMASI | E55: 6.672321, -1.651491 | F55: 6.696086°, -1.617477° | G55: {=_xlfn.IFS(J55<301,2,J55>300,48)} -> 48 | H55: KUMASI | I55: 0 | J55: 1800 | K55: =IF(M55="ONT",20,IF(M55="N/A","N/A",IF(M55="MIKROTIK",IF(J55<3000,10,IF(3000<J55>10000,20,IF(10000<J55>20000,40,IF(20000<J55>40000,60,IF(J55>40000,80,IF(J55<300,3,))))))))) -> 20 | M55: ONT | N55: ADSS | O55: 2021 | P55: 44400 | Q55: July | S55: ACTIVE | T55: Yes
A56: 55 | B56: ASHANTI | C56: ECG | D56: LONGFORD ROYAL HOTEL | E56: 6.727498, -1.581914 | F56: 6.696086°, -1.617477° | G56: {=_xlfn.IFS(J56<301,2,J56>300,48)} -> 48 | H56: KUMASI | I56: 0 | J56: 1800 | K56: =IF(M56="ONT",20,IF(M56="N/A","N/A",IF(M56="MIKROTIK",IF(J56<3000,10,IF(3000<J56>10000,20,IF(10000<J56>20000,40,IF(20000<J56>40000,60,IF(J56>40000,80,IF(J56<300,3,))))))))) -> 10 | M56: MIKROTIK | N56: ADSS | O56: 2021 | P56: 44400 | Q56: July | S56: ACTIVE | T56: Yes
A57: 56 | B57: ASHANTI | C57: ECG | D57: ODENEHO TSE ADDO MAYFAIR | E57: 5.610061, -0.141144 | F57: 5.584144, -0.164072 | G57: {=_xlfn.IFS(J57<301,2,J57>300,48)} -> 48 | H57: TSE ADDO | I57: 0 | J57: 2500 | K57: =IF(M57="ONT",20,IF(M57="N/A","N/A",IF(M57="MIKROTIK",IF(J57<3000,10,IF(3000<J57>10000,20,IF(10000<J57>20000,40,IF(20000<J57>40000,60,IF(J57>40000,80,IF(J57<300,3,))))))))) -> 20 | M57: ONT | N57: ADSS | O57: 2021 | P57: 44383 | Q57: July | S57: ACTIVE | T57: Yes
A58: 57 | B58: ASHANTI | C58: ECG | D58: ABSA ASAFO BRANCH | E58: 6.684504, -1.614025 | F58: 5.584144, -0.164072 | G58: {=_xlfn.IFS(J58<301,2,J58>300,48)} -> 48 | H58: KUMASI | I58: 0 | J58: 1500 | K58: =IF(M58="ONT",20,IF(M58="N/A","N/A",IF(M58="MIKROTIK",IF(J58<3000,10,IF(3000<J58>10000,20,IF(10000<J58>20000,40,IF(20000<J58>40000,60,IF(J58>40000,80,IF(J58<300,3,))))))))) -> 20 | M58: ONT | N58: ADSS | O58: 2022 | P58: 44568 | Q58: January | S58: ACTIVE | T58: Yes
A59: 58 | B59: ASHANTI | C59: ECG | D59: ABSA KROFROM | E59: 6.713413,-1.615592 | F59: 6.696086°, -1.617477° | G59: {=_xlfn.IFS(J59<301,2,J59>300,48)} -> 48 | H59: Krofrom | I59: 0 | J59: 400 | K59: =IF(M59="ONT",20,IF(M59="N/A","N/A",IF(M59="MIKROTIK",IF(J59<3000,10,IF(3000<J59>10000,20,IF(10000<J59>20000,40,IF(20000<J59>40000,60,IF(J59>40000,80,IF(J59<300,3,))))))))) -> 20 | M59: ONT | N59: ADSS | O59: 2021 | S59: ACTIVE | T59: Yes
A60: 59 | B60: ASHANTI | C60: ECG | D60: ABSA KUMASI KPST MAIN AND PLC /PREMPEH | E60: 6.689871,-1.622878 | F60: 6.696086°, -1.617477° | G60: {=_xlfn.IFS(J60<301,2,J60>300,48)} -> 48 | H60: KUMASI | I60: 0 | J60: 800 | K60: =IF(M60="ONT",20,IF(M60="N/A","N/A",IF(M60="MIKROTIK",IF(J60<3000,10,IF(3000<J60>10000,20,IF(10000<J60>20000,40,IF(20000<J60>40000,60,IF(J60>40000,80,IF(J60<300,3,))))))))) -> 20 | M60: ONT | N60: ADSS | O60: 2021 | S60: ACTIVE | T60: Yes
A61: 60 | B61: ASHANTI | C61: ECG | D61: ABSA SUAME MAGAZINE/ OLD SUAME | E61: 6.728684,-1.63248 | F61: 6.696086°, -1.617477° | G61: {=_xlfn.IFS(J61<301,2,J61>300,48)} -> 48 | H61: SUAME | I61: 0 | J61: 400 | K61: =IF(M61="ONT",20,IF(M61="N/A","N/A",IF(M61="MIKROTIK",IF(J61<3000,10,IF(3000<J61>10000,20,IF(10000<J61>20000,40,IF(20000<J61>40000,60,IF(J61>40000,80,IF(J61<300,3,))))))))) -> 20 | M61: ONT | N61: ADSS | O61: 2021 | S61: ACTIVE | T61: Yes
A62: 61 | B62: ASHANTI | C62: ECG | D62: ABSA TAFO | E62: 6.739561,-1.611229 | F62: 6.708775, -1.627550 | G62: {=_xlfn.IFS(J62<301,2,J62>300,48)} -> 48 | H62: TAFO | I62: 0 | J62: 400 | K62: =IF(M62="ONT",20,IF(M62="N/A","N/A",IF(M62="MIKROTIK",IF(J62<3000,10,IF(3000<J62>10000,20,IF(10000<J62>20000,40,IF(20000<J62>40000,60,IF(J62>40000,80,IF(J62<300,3,))))))))) -> 20 | M62: ONT | N62: ADSS | O62: 2021 | S62: ACTIVE | T62: Yes
A63: 62 | B63: ASHANTI | C63: ECG | D63: ABSA TANOSO | E63: 6.696178,-1.68193 | F63: 6.708775, -1.627550 | G63: {=_xlfn.IFS(J63<301,2,J63>300,48)} -> 2 | H63: TANOSO | I63: 0 | J63: 300 | K63: =IF(M63="ONT",20,IF(M63="N/A","N/A",IF(M63="MIKROTIK",IF(J63<3000,10,IF(3000<J63>10000,20,IF(10000<J63>20000,40,IF(20000<J63>40000,60,IF(J63>40000,80,IF(J63<300,3,))))))))) -> 20 | M63: ONT | N63: ADSS | O63: 2021 | S63: ACTIVE | T63: Yes
A64: 63 | B64: ASHANTI | C64: ECG | D64: ABSA BANTAMA | E64: 642'23.50"N 138'10.85"W | F64: 6.708775, -1.627550 | G64: {=_xlfn.IFS(J64<301,2,J64>300,48)} -> 48 | H64: BANTAMA | I64: 0 | J64: 350 | K64: =IF(M64="ONT",20,IF(M64="N/A","N/A",IF(M64="MIKROTIK",IF(J64<3000,10,IF(3000<J64>10000,20,IF(10000<J64>20000,40,IF(20000<J64>40000,60,IF(J64>40000,80,IF(J64<300,3,))))))))) -> 20 | M64: ONT | N64: ADSS | O64: 2021 | S64: ACTIVE | T64: Yes
A65: 64 | B65: ASHANTI | C65: ECG | D65: SAN_ERNEST CHEMIST_KUM_SANTASE | E65: 640'15.41"N 138'16.08"W | F65: 6.708775, -1.627550 | G65: {=_xlfn.IFS(J65<301,2,J65>300,48)} -> 48 | H65: SANTASI | I65: 0 | J65: 700 | K65: =IF(M65="ONT",20,IF(M65="N/A","N/A",IF(M65="MIKROTIK",IF(J65<3000,10,IF(3000<J65>10000,20,IF(10000<J65>20000,40,IF(20000<J65>40000,60,IF(J65>40000,80,IF(J65<300,3,))))))))) -> 20 | M65: ONT | N65: ADSS | O65: 2021 | P65: 44534 | Q65: December | S65: ACTIVE | T65: Yes
A66: 65 | B66: ASHANTI | C66: ECG | D66: SPORT BETTING GROUP KUMASI | E66: 6.687589 -1.607350 | F66: 6.708775, -1.627550 | G66: {=_xlfn.IFS(J66<301,2,J66>300,48)} -> 48 | H66: KUMASI | I66: 0 | J66: 700 | K66: =IF(M66="ONT",20,IF(M66="N/A","N/A",IF(M66="MIKROTIK",IF(J66<3000,10,IF(3000<J66>10000,20,IF(10000<J66>20000,40,IF(20000<J66>40000,60,IF(J66>40000,80,IF(J66<300,3,))))))))) -> 20 | M66: ONT | N66: ADSS | O66: 2021 | S66: ACTIVE | T66: Yes
A67: 66 | B67: ASHANTI | C67: ECG | D67: ASANTEMAN - BROADSPECTRUM | E67: 6.678250, -1.616044 | F67: 6.708775, -1.627550 | G67: {=_xlfn.IFS(J67<301,2,J67>300,48)} -> 48 | H67: KUMASI | I67: 0 | J67: 3500 | K67: =IF(M67="ONT",20,IF(M67="N/A","N/A",IF(M67="MIKROTIK",IF(J67<3000,10,IF(3000<J67>10000,20,IF(10000<J67>20000,40,IF(20000<J67>40000,60,IF(J67>40000,80,IF(J67<300,3,))))))))) -> 20 | M67: MIKROTIK | N67: ADSS | O67: 2021 | S67: ACTIVE | T67: Yes
A68: 67 | B68: ASHANTI | C68: ECG | D68: ASAFO BRANCH | E68: 6.684504,-1.614025 | F68: 6.708775, -1.627550 | G68: {=_xlfn.IFS(J68<301,2,J68>300,48)} -> 48 | H68: KUMASI | I68: 0 | J68: 1129.8 | K68: =IF(M68="ONT",20,IF(M68="N/A","N/A",IF(M68="MIKROTIK",IF(J68<3000,10,IF(3000<J68>10000,20,IF(10000<J68>20000,40,IF(20000<J68>40000,60,IF(J68>40000,80,IF(J68<300,3,))))))))) -> FALSE | M68: VSOL 1RD | N68: ADSS | O68: 2021 | S68: ACTIVE | T68: Yes
A69: 68 | B69: ASHANTI | C69: ECG | D69: ODEHENO | E69: 6.672321,-1.651491 | F69: 6.708775, -1.627550 | G69: {=_xlfn.IFS(J69<301,2,J69>300,48)} -> 48 | H69: KUMASI | I69: 0 | J69: 577.5 | K69: =IF(M69="ONT",20,IF(M69="N/A","N/A",IF(M69="MIKROTIK",IF(J69<3000,10,IF(3000<J69>10000,20,IF(10000<J69>20000,40,IF(20000<J69>40000,60,IF(J69>40000,80,IF(J69<300,3,))))))))) -> 10 | M69: MIKROTIK | N69: ADSS | O69: 2021 | S69: ACTIVE | T69: Yes
A70: 69 | B70: ASHANTI | C70: ECG | D70: LANGFORD HOTEL | E70: 6.727498, -1.581914 | F70: 6.708775, -1.627550 | G70: {=_xlfn.IFS(J70<301,2,J70>300,48)} -> 48 | H70: KUMASI | I70: 0 | J70: 3715.95 | K70: =IF(M70="ONT",20,IF(M70="N/A","N/A",IF(M70="MIKROTIK",IF(J70<3000,10,IF(3000<J70>10000,20,IF(10000<J70>20000,40,IF(20000<J70>40000,60,IF(J70>40000,80,IF(J70<300,3,))))))))) -> 20 | M70: MIKROTIK | N70: ADSS | O70: 2021 | S70: ACTIVE | T70: Yes
A71: 70 | B71: ASHANTI | C71: ECG | D71: BOADI F TO KNUST | E71: 6.686874, -1.545754 | F71: 6°41'12.91"N 1°32'44.65"W | G71: 24 | H71: KUMASI | I71: 0 | J71: 4048.8 | K71: =IF(M71="ONT",20,IF(M71="N/A","N/A",IF(M71="MIKROTIK",IF(J71<3000,10,IF(3000<J71>10000,20,IF(10000<J71>20000,40,IF(20000<J71>40000,60,IF(J71>40000,80,IF(J71<300,3,))))))))) -> N/A | M71: N/A | N71: ADSS | O71: 2022 | S71: ACTIVE | T71: Yes
A72: 71 | B72: ASHANTI | C72: ECG | D72: CROP RESEARCH INSTITUTE | E72: 6.710169,-1.527967 | F72: 6.696086°, -1.617477° | G72: {=_xlfn.IFS(J72<301,2,J72>300,48)} -> 48 | H72: KUMASI | I72: 0 | J72: 567 | K72: =IF(M72="ONT",20,IF(M72="N/A","N/A",IF(M72="MIKROTIK",IF(J72<3000,10,IF(3000<J72>10000,20,IF(10000<J72>20000,40,IF(20000<J72>40000,60,IF(J72>40000,80,IF(J72<300,3,))))))))) -> 10 | M72: MIKROTIK | N72: ADSS | O72: 2020 | S72: ACTIVE | T72: Yes
A73: 72 | B73: ASHANTI | C73: ECG | D73: GOLDEN TULIP KUMASI | E73: 6.682457, -1.625554 | F73: 6.696086°, -1.617477° | G73: {=_xlfn.IFS(J73<301,2,J73>300,48)} -> 48 | H73: KUMASI | I73: 0 | J73: 315 | K73: =IF(M73="ONT",20,IF(M73="N/A","N/A",IF(M73="MIKROTIK",IF(J73<3000,10,IF(3000<J73>10000,20,IF(10000<J73>20000,40,IF(20000<J73>40000,60,IF(J73>40000,80,IF(J73<300,3,))))))))) -> N/A | M73: N/A | N73: ADSS | O73: 2021 | S73: ACTIVE | T73: Yes
A74: 73 | B74: ASHANTI | C74: ECG | D74: INTERNATIONAL COMMUNITY SCHOOL, AJAMESU | E74: 6.537139,-1.668662 | F74: 6.696086°, -1.617477° | G74: {=_xlfn.IFS(J74<301,2,J74>300,48)} -> 48 | H74: KUMASI | I74: 0 | J74: 400 | K74: =IF(M74="ONT",20,IF(M74="N/A","N/A",IF(M74="MIKROTIK",IF(J74<3000,10,IF(3000<J74>10000,20,IF(10000<J74>20000,40,IF(20000<J74>40000,60,IF(J74>40000,80,IF(J74<300,3,))))))))) -> 10 | M74: MIKROTIK | N74: ADSS | O74: 2021 | S74: ACTIVE | T74: Yes
A75: 74 | B75: ASHANTI | C75: ECG | D75: JACKSON COMPLEX 2 | E75: 6.6891,-1.6352 | F75: 6.708775, -1.627550 | G75: {=_xlfn.IFS(J75<301,2,J75>300,48)} -> 48 | H75: KUMASI | I75: 0 | J75: 3963.75 | K75: =IF(M75="ONT",20,IF(M75="N/A","N/A",IF(M75="MIKROTIK",IF(J75<3000,10,IF(3000<J75>10000,20,IF(10000<J75>20000,40,IF(20000<J75>40000,60,IF(J75>40000,80,IF(J75<300,3,))))))))) -> 20 | M75: MIKROTIK | N75: ADSS | O75: 2020 | S75: ACTIVE | T75: Yes
